2025-07-07 21:19:20,484 - main - INFO - save_files:122 - Запуск приложения резервного копирования
2025-07-07 21:19:20,484 - __main__ - INFO - save_files:23 - Инициализация SaveFiles
2025-07-07 21:19:20,504 - __main__ - INFO - save_files:47 - Начало создания и загрузки архива
2025-07-07 21:19:20,504 - arch_7z_spec - INFO - arch_7z_spec:112 - Запуск архивации: ['C:\\Users\\LB\\Downloads\\7-Zip\\7z.exe', 'a', '-p1 2', '-mhe=on', '-sfx', 'C:\\Users\\LB\\AppData\\Local\\Temp\\tmpfav1gmz_\\archive.exe', '@C:\\PycharmProjects\\Save\\list.txt', '-bso0', '-bsp0']
2025-07-07 21:19:25,490 - arch_7z_spec - INFO - arch_7z_spec:137 - Архивация завершена успешно
2025-07-07 21:19:25,491 - __main__ - INFO - save_files:64 - Архив успешно создан
2025-07-07 21:19:25,491 - yandex_disk - INFO - yandex_disk:51 - Инициализация YandexDisk
2025-07-07 21:19:25,491 - yandex_disk - INFO - yandex_disk:67 - Получение токена авторизации
2025-07-07 21:19:25,493 - __main__ - INFO - save_files:67 - Начало загрузки на Яндекс.Диск
2025-07-07 21:19:25,493 - yandex_disk - INFO - yandex_disk:231 - Быстрая загрузка файла C:\Users\LB\AppData\Local\Temp\tmpfav1gmz_\archive.exe
2025-07-07 21:19:25,493 - yandex_disk - INFO - yandex_disk:81 - Генерация имени архива
2025-07-07 21:19:26,686 - yandex_disk - WARNING - yandex_disk:119 - Папка disk:/Архивы не найдена, создаем
2025-07-07 21:19:27,400 - yandex_disk - INFO - yandex_disk:121 - Папка disk:/Архивы создана
2025-07-07 21:19:27,400 - yandex_disk - INFO - yandex_disk:93 - Сгенерировано имя архива: archive_2025_07_07_1.exe
2025-07-07 21:19:28,375 - yandex_disk - INFO - yandex_disk:237 - Начало загрузки файла C:\Users\LB\AppData\Local\Temp\tmpfav1gmz_\archive.exe
2025-07-07 21:20:17,123 - yandex_disk - INFO - yandex_disk:242 - Файл C:\Users\LB\AppData\Local\Temp\tmpfav1gmz_\archive.exe успешно загружен в archive_2025_07_07_1.exe
2025-07-07 21:20:17,124 - __main__ - INFO - save_files:73 - Архив успешно загружен на Яндекс.Диск
2025-07-07 21:20:17,134 - main - INFO - save_files:127 - Процесс завершен успешно
2025-07-07 21:28:17,357 - main - INFO - save_files:122 - Запуск приложения резервного копирования
2025-07-07 21:28:17,358 - __main__ - INFO - save_files:23 - Инициализация SaveFiles
2025-07-07 21:28:17,379 - __main__ - INFO - save_files:47 - Начало создания и загрузки архива
2025-07-07 21:28:17,379 - arch_7z_spec - INFO - arch_7z_spec:115 - Запуск архивации: ['C:\\Users\\LB\\Downloads\\7-Zip\\7z.exe', 'a', ('-p***************',), '-mhe=on', '-sfx', 'C:\\Users\\LB\\AppData\\Local\\Temp\\tmpdnzgnmjd\\archive.exe', '@C:\\PycharmProjects\\Save\\list.txt', '-bso0', '-bsp0']
2025-07-07 21:28:17,380 - arch_7z_spec - ERROR - arch_7z_spec:128 - Ошибка при запуске процесса архивации
Traceback (most recent call last):
  File "C:\PycharmProjects\Save\SRC\arch_7z_spec.py", line 118, in make_archive
    process = subprocess.run(
        cmd,
    ...<4 lines>...
        cwd=self.work_dir,  # Указываем рабочую директорию
    )
  File "C:\Program Files\WindowsApps\PythonSoftwareFoundation.Python.3.13_3.13.1520.0_x64__qbz5n2kfra8p0\Lib\subprocess.py", line 554, in run
    with Popen(*popenargs, **kwargs) as process:
         ~~~~~^^^^^^^^^^^^^^^^^^^^^^
  File "C:\Program Files\WindowsApps\PythonSoftwareFoundation.Python.3.13_3.13.1520.0_x64__qbz5n2kfra8p0\Lib\subprocess.py", line 1039, in __init__
    self._execute_child(args, executable, preexec_fn, close_fds,
    ~~~~~~~~~~~~~~~~~~~^^^^^^^^^^^^^^^^^^^^^^^^^^^^^^^^^^^^^^^^^
                        pass_fds, cwd, env,
                        ^^^^^^^^^^^^^^^^^^^
    ...<5 lines>...
                        gid, gids, uid, umask,
                        ^^^^^^^^^^^^^^^^^^^^^^
                        start_new_session, process_group)
                        ^^^^^^^^^^^^^^^^^^^^^^^^^^^^^^^^^
  File "C:\Program Files\WindowsApps\PythonSoftwareFoundation.Python.3.13_3.13.1520.0_x64__qbz5n2kfra8p0\Lib\subprocess.py", line 1478, in _execute_child
    args = list2cmdline(args)
  File "C:\Program Files\WindowsApps\PythonSoftwareFoundation.Python.3.13_3.13.1520.0_x64__qbz5n2kfra8p0\Lib\subprocess.py", line 614, in list2cmdline
    for arg in map(os.fsdecode, seq):
               ~~~^^^^^^^^^^^^^^^^^^
  File "<frozen os>", line 862, in fsdecode
TypeError: expected str, bytes or os.PathLike object, not tuple
2025-07-07 21:28:17,382 - __main__ - ERROR - save_files:61 - Ошибка создания архива
2025-07-07 21:28:17,383 - __main__ - ERROR - save_files:76 - Критическая ошибка в make_and_write_archive
Traceback (most recent call last):
  File "C:\PycharmProjects\Save\SRC\save_files.py", line 62, in make_and_write_archive
    raise OSError("Не удалось создать архив") from None
OSError: Не удалось создать архив
2025-07-07 21:28:17,383 - main - ERROR - save_files:130 - Критическая ошибка при формировании или записи архива в облако
Traceback (most recent call last):
  File "C:\PycharmProjects\Save\SRC\save_files.py", line 126, in <module>
    save_files.make_and_write_archive()
    ~~~~~~~~~~~~~~~~~~~~~~~~~~~~~~~~~^^
  File "C:\PycharmProjects\Save\SRC\save_files.py", line 62, in make_and_write_archive
    raise OSError("Не удалось создать архив") from None
OSError: Не удалось создать архив
2025-07-07 21:30:53,567 - main - INFO - save_files:122 - Запуск приложения резервного копирования
2025-07-07 21:30:53,568 - __main__ - INFO - save_files:23 - Инициализация SaveFiles
2025-07-07 21:30:53,590 - __main__ - INFO - save_files:47 - Начало создания и загрузки архива
2025-07-07 21:30:53,591 - arch_7z_spec - INFO - arch_7z_spec:116 - Запуск архивации: ['C:\\Users\\LB\\Downloads\\7-Zip\\7z.exe', 'a', '-p1 2', '-mhe=on', '-sfx', 'C:\\Users\\LB\\AppData\\Local\\Temp\\tmpbsnv1ywl\\archive.exe', '@C:\\PycharmProjects\\Save\\list.txt', '-bso0', '-bsp0']
2025-07-07 21:30:58,434 - arch_7z_spec - INFO - arch_7z_spec:141 - Архивация завершена успешно
2025-07-07 21:30:58,434 - __main__ - INFO - save_files:64 - Архив успешно создан
2025-07-07 21:30:58,434 - yandex_disk - INFO - yandex_disk:51 - Инициализация YandexDisk
2025-07-07 21:30:58,434 - yandex_disk - INFO - yandex_disk:67 - Получение токена авторизации
2025-07-07 21:30:58,435 - __main__ - INFO - save_files:67 - Начало загрузки на Яндекс.Диск
2025-07-07 21:30:58,436 - yandex_disk - INFO - yandex_disk:231 - Быстрая загрузка файла C:\Users\LB\AppData\Local\Temp\tmpbsnv1ywl\archive.exe
2025-07-07 21:30:58,436 - yandex_disk - INFO - yandex_disk:81 - Генерация имени архива
2025-07-07 21:30:59,744 - yandex_disk - INFO - yandex_disk:93 - Сгенерировано имя архива: archive_2025_07_07_2.exe
2025-07-07 21:31:00,768 - yandex_disk - INFO - yandex_disk:237 - Начало загрузки файла C:\Users\LB\AppData\Local\Temp\tmpbsnv1ywl\archive.exe
2025-07-07 21:31:39,307 - yandex_disk - INFO - yandex_disk:242 - Файл C:\Users\LB\AppData\Local\Temp\tmpbsnv1ywl\archive.exe успешно загружен в archive_2025_07_07_2.exe
2025-07-07 21:31:39,308 - __main__ - INFO - save_files:73 - Архив успешно загружен на Яндекс.Диск
2025-07-07 21:31:39,316 - main - INFO - save_files:127 - Процесс завершен успешно
2025-07-07 21:41:11,351 - main - INFO - save_files:122 - Запуск приложения резервного копирования
2025-07-07 21:41:11,351 - __main__ - INFO - save_files:23 - Инициализация SaveFiles
2025-07-07 21:41:11,373 - __main__ - INFO - save_files:47 - Начало создания и загрузки архива
2025-07-07 21:41:11,373 - arch_7z_spec - INFO - arch_7z_spec:116 - Запуск архивации: ['C:\\Users\\LB\\Downloads\\7-Zip\\7z.exe', 'a', ('-p***************',), '-mhe=on', '-sfx', 'C:\\Users\\LB\\AppData\\Local\\Temp\\tmp0xnwdx6a\\archive.exe', '@C:\\PycharmProjects\\Save\\list.txt', '-bso0', '-bsp0']
2025-07-07 21:41:16,415 - arch_7z_spec - INFO - arch_7z_spec:141 - Архивация завершена успешно
2025-07-07 21:41:16,415 - __main__ - INFO - save_files:64 - Архив успешно создан
2025-07-07 21:41:16,415 - yandex_disk - INFO - yandex_disk:51 - Инициализация YandexDisk
2025-07-07 21:41:16,415 - yandex_disk - INFO - yandex_disk:67 - Получение токена авторизации
2025-07-07 21:41:16,417 - __main__ - INFO - save_files:67 - Начало загрузки на Яндекс.Диск
2025-07-07 21:41:16,417 - yandex_disk - INFO - yandex_disk:231 - Быстрая загрузка файла C:\Users\LB\AppData\Local\Temp\tmp0xnwdx6a\archive.exe
2025-07-07 21:41:16,417 - yandex_disk - INFO - yandex_disk:81 - Генерация имени архива
2025-07-07 21:41:17,334 - yandex_disk - INFO - yandex_disk:93 - Сгенерировано имя архива: archive_2025_07_07_3.exe
2025-07-07 21:41:18,187 - yandex_disk - INFO - yandex_disk:237 - Начало загрузки файла C:\Users\LB\AppData\Local\Temp\tmp0xnwdx6a\archive.exe
2025-07-07 21:42:16,341 - yandex_disk - INFO - yandex_disk:242 - Файл C:\Users\LB\AppData\Local\Temp\tmp0xnwdx6a\archive.exe успешно загружен в archive_2025_07_07_3.exe
2025-07-07 21:42:16,342 - __main__ - INFO - save_files:73 - Архив успешно загружен на Яндекс.Диск
2025-07-07 21:42:16,356 - main - INFO - save_files:127 - Процесс завершен успешно
2025-07-07 21:43:01,990 - main - INFO - save_files:122 - Запуск приложения резервного копирования
2025-07-07 21:43:01,991 - __main__ - INFO - save_files:23 - Инициализация SaveFiles
2025-07-07 21:43:02,015 - __main__ - INFO - save_files:47 - Начало создания и загрузки архива
2025-07-07 21:43:02,015 - arch_7z_spec - INFO - arch_7z_spec:115 - Запуск архивации: ['C:\\Users\\LB\\Downloads\\7-Zip\\7z.exe', 'a', ['-p***************'], '-mhe=on', '-sfx', 'C:\\Users\\LB\\AppData\\Local\\Temp\\tmp83l9a4di\\archive.exe', '@C:\\PycharmProjects\\Save\\list.txt', '-bso0', '-bsp0']
2025-07-07 21:43:07,073 - arch_7z_spec - INFO - arch_7z_spec:140 - Архивация завершена успешно
2025-07-07 21:43:07,073 - __main__ - INFO - save_files:64 - Архив успешно создан
2025-07-07 21:43:07,073 - yandex_disk - INFO - yandex_disk:51 - Инициализация YandexDisk
2025-07-07 21:43:07,073 - yandex_disk - INFO - yandex_disk:67 - Получение токена авторизации
2025-07-07 21:43:07,074 - __main__ - INFO - save_files:67 - Начало загрузки на Яндекс.Диск
2025-07-07 21:43:07,074 - yandex_disk - INFO - yandex_disk:231 - Быстрая загрузка файла C:\Users\LB\AppData\Local\Temp\tmp83l9a4di\archive.exe
2025-07-07 21:43:07,074 - yandex_disk - INFO - yandex_disk:81 - Генерация имени архива
2025-07-07 21:43:08,145 - yandex_disk - INFO - yandex_disk:93 - Сгенерировано имя архива: archive_2025_07_07_4.exe
2025-07-07 21:43:09,022 - yandex_disk - INFO - yandex_disk:237 - Начало загрузки файла C:\Users\LB\AppData\Local\Temp\tmp83l9a4di\archive.exe
2025-07-07 21:44:59,256 - main - INFO - save_files:122 - Запуск приложения резервного копирования
2025-07-07 21:44:59,257 - __main__ - INFO - save_files:23 - Инициализация SaveFiles
2025-07-07 21:44:59,279 - __main__ - INFO - save_files:47 - Начало создания и загрузки архива
2025-07-07 21:44:59,279 - arch_7z_spec - INFO - arch_7z_spec:115 - Запуск архивации: ['C:\\Users\\LB\\Downloads\\7-Zip\\7z.exe', 'a', '-p***************', '-mhe=on', '-sfx', 'C:\\Users\\LB\\AppData\\Local\\Temp\\tmp15cml7v0\\archive.exe', '@C:\\PycharmProjects\\Save\\list.txt', '-bso0', '-bsp0']
2025-07-07 21:45:04,158 - arch_7z_spec - INFO - arch_7z_spec:140 - Архивация завершена успешно
2025-07-07 21:45:04,159 - __main__ - INFO - save_files:64 - Архив успешно создан
2025-07-07 21:45:04,159 - yandex_disk - INFO - yandex_disk:51 - Инициализация YandexDisk
2025-07-07 21:45:04,159 - yandex_disk - INFO - yandex_disk:67 - Получение токена авторизации
2025-07-07 21:45:04,160 - __main__ - INFO - save_files:67 - Начало загрузки на Яндекс.Диск
2025-07-07 21:45:04,160 - yandex_disk - INFO - yandex_disk:231 - Быстрая загрузка файла C:\Users\LB\AppData\Local\Temp\tmp15cml7v0\archive.exe
2025-07-07 21:45:04,160 - yandex_disk - INFO - yandex_disk:81 - Генерация имени архива
2025-07-07 21:45:05,111 - yandex_disk - INFO - yandex_disk:93 - Сгенерировано имя архива: archive_2025_07_07_4.exe
2025-07-07 21:45:05,986 - yandex_disk - INFO - yandex_disk:237 - Начало загрузки файла C:\Users\LB\AppData\Local\Temp\tmp15cml7v0\archive.exe
2025-07-07 21:49:17,539 - main - INFO - save_files:122 - Запуск приложения резервного копирования
2025-07-07 21:49:17,540 - __main__ - INFO - save_files:23 - Инициализация SaveFiles
2025-07-07 21:49:17,561 - root - ERROR - save_files:41 - Отсутствуют ENV переменные: PASSWORD
2025-07-07 21:49:17,561 - main - ERROR - save_files:130 - Критическая ошибка при формировании или записи архива в облако
Traceback (most recent call last):
  File "C:\PycharmProjects\Save\SRC\save_files.py", line 125, in <module>
    save_files = SaveFiles()
  File "C:\PycharmProjects\Save\SRC\save_files.py", line 33, in __init__
    self.init_env()
    ~~~~~~~~~~~~~^^
  File "C:\PycharmProjects\Save\SRC\save_files.py", line 42, in init_env
    raise EnvironmentError(
        f"Отсутствуют обязательные ENV переменные: {', '.join(missing)}"
    ) from None
OSError: Отсутствуют обязательные ENV переменные: PASSWORD
2025-07-07 21:50:17,313 - main - INFO - save_files:122 - Запуск приложения резервного копирования
2025-07-07 21:50:17,313 - __main__ - INFO - save_files:23 - Инициализация SaveFiles
2025-07-07 21:50:17,339 - root - ERROR - save_files:41 - Отсутствуют ENV переменные: PASSWORD
2025-07-07 21:50:17,339 - main - ERROR - save_files:130 - Критическая ошибка при формировании или записи архива в облако
Traceback (most recent call last):
  File "C:\PycharmProjects\Save\SRC\save_files.py", line 125, in <module>
    save_files = SaveFiles()
  File "C:\PycharmProjects\Save\SRC\save_files.py", line 33, in __init__
    self.init_env()
    ~~~~~~~~~~~~~^^
  File "C:\PycharmProjects\Save\SRC\save_files.py", line 42, in init_env
    raise EnvironmentError(
        f"Отсутствуют обязательные ENV переменные: {', '.join(missing)}"
    ) from None
OSError: Отсутствуют обязательные ENV переменные: PASSWORD
2025-07-07 21:53:04,302 - main - INFO - save_files:122 - Запуск приложения резервного копирования
2025-07-07 21:53:04,303 - __main__ - INFO - save_files:23 - Инициализация SaveFiles
2025-07-07 21:53:04,324 - __main__ - INFO - save_files:47 - Начало создания и загрузки архива
2025-07-07 21:53:04,325 - arch_7z_spec - INFO - arch_7z_spec:115 - Запуск архивации: ['C:\\Users\\LB\\Downloads\\7-Zip\\7z.exe', 'a', '-p***************', '-mhe=on', '-sfx', 'C:\\Users\\LB\\AppData\\Local\\Temp\\tmpgj40legw\\archive.exe', '@C:\\PycharmProjects\\Save\\list.txt', '-bso0', '-bsp0']
2025-07-07 21:53:09,283 - arch_7z_spec - INFO - arch_7z_spec:140 - Архивация завершена успешно
2025-07-07 21:53:09,283 - __main__ - INFO - save_files:64 - Архив успешно создан
2025-07-07 21:53:09,283 - yandex_disk - INFO - yandex_disk:51 - Инициализация YandexDisk
2025-07-07 21:53:09,283 - yandex_disk - INFO - yandex_disk:67 - Получение токена авторизации
2025-07-07 21:53:09,284 - __main__ - INFO - save_files:67 - Начало загрузки на Яндекс.Диск
2025-07-07 21:53:09,284 - yandex_disk - INFO - yandex_disk:231 - Быстрая загрузка файла C:\Users\LB\AppData\Local\Temp\tmpgj40legw\archive.exe
2025-07-07 21:53:09,284 - yandex_disk - INFO - yandex_disk:81 - Генерация имени архива
2025-07-07 21:53:10,049 - yandex_disk - INFO - yandex_disk:93 - Сгенерировано имя архива: archive_2025_07_07_4.exe
2025-07-07 21:53:11,048 - yandex_disk - INFO - yandex_disk:237 - Начало загрузки файла C:\Users\LB\AppData\Local\Temp\tmpgj40legw\archive.exe
2025-07-07 21:53:56,593 - yandex_disk - INFO - yandex_disk:242 - Файл C:\Users\LB\AppData\Local\Temp\tmpgj40legw\archive.exe успешно загружен в archive_2025_07_07_4.exe
2025-07-07 21:53:56,594 - __main__ - INFO - save_files:73 - Архив успешно загружен на Яндекс.Диск
2025-07-07 21:53:56,605 - main - INFO - save_files:127 - Процесс завершен успешно
2025-07-07 22:13:46,183 - main - INFO - save_files:134 - Запуск приложения резервного копирования
2025-07-07 22:13:46,186 - __main__ - INFO - save_files:22 - Инициализация SaveFiles
2025-07-07 22:13:46,207 - __main__ - INFO - save_files:52 - Начало создания и загрузки архива
2025-07-07 22:13:46,207 - arch_7z_spec - INFO - arch_7z_spec:115 - Запуск архивации: ['C:\\Users\\LB\\Downloads\\7-Zip\\7z.exe', 'a', '-p***************', '-mhe=on', '-sfx', 'C:\\Users\\LB\\AppData\\Local\\Temp\\tmpul83o858\\archive.exe', '@C:\\PycharmProjects\\Save\\list.txt', '-bso0', '-bsp0']
2025-07-07 22:13:51,096 - arch_7z_spec - INFO - arch_7z_spec:140 - Архивация завершена успешно
2025-07-07 22:13:51,096 - __main__ - INFO - save_files:69 - Архив успешно создан
2025-07-07 22:13:51,096 - yandex_disk - INFO - yandex_disk:51 - Инициализация YandexDisk
2025-07-07 22:13:51,096 - yandex_disk - INFO - yandex_disk:67 - Получение токена авторизации
2025-07-07 22:13:51,097 - __main__ - INFO - save_files:72 - Начало загрузки на Яндекс.Диск
2025-07-07 22:13:51,097 - yandex_disk - INFO - yandex_disk:231 - Быстрая загрузка файла C:\Users\LB\AppData\Local\Temp\tmpul83o858\archive.exe
2025-07-07 22:13:51,097 - yandex_disk - INFO - yandex_disk:81 - Генерация имени архива
2025-07-07 22:13:52,008 - yandex_disk - INFO - yandex_disk:93 - Сгенерировано имя архива: archive_2025_07_07_5.exe
2025-07-07 22:13:53,219 - yandex_disk - INFO - yandex_disk:237 - Начало загрузки файла C:\Users\LB\AppData\Local\Temp\tmpul83o858\archive.exe
2025-07-07 22:14:23,555 - yandex_disk - INFO - yandex_disk:242 - Файл C:\Users\LB\AppData\Local\Temp\tmpul83o858\archive.exe успешно загружен в archive_2025_07_07_5.exe
2025-07-07 22:14:23,557 - __main__ - INFO - save_files:78 - Архив успешно загружен на Яндекс.Диск
2025-07-07 22:14:23,571 - main - INFO - save_files:139 - Процесс завершен успешно
2025-07-07 22:14:23,571 - main - INFO - save_files:147 - Запуск приложения резервного копирования
2025-07-07 22:14:23,571 - main - INFO - save_files:147 - Запуск приложения резервного копирования
2025-07-07 22:14:23,571 - __main__ - INFO - save_files:22 - Инициализация SaveFiles
2025-07-07 22:14:23,571 - __main__ - INFO - save_files:22 - Инициализация SaveFiles
2025-07-07 22:14:23,588 - __main__ - INFO - save_files:52 - Начало создания и загрузки архива
2025-07-07 22:14:23,588 - __main__ - INFO - save_files:52 - Начало создания и загрузки архива
2025-07-07 22:14:23,589 - arch_7z_spec - INFO - arch_7z_spec:115 - Запуск архивации: ['C:\\Users\\LB\\Downloads\\7-Zip\\7z.exe', 'a', '-p***************', '-mhe=on', '-sfx', 'C:\\Users\\LB\\AppData\\Local\\Temp\\tmpuiq1bw8i\\archive.exe', '@C:\\PycharmProjects\\Save\\list.txt', '-bso0', '-bsp0']
2025-07-07 22:14:23,589 - arch_7z_spec - INFO - arch_7z_spec:115 - Запуск архивации: ['C:\\Users\\LB\\Downloads\\7-Zip\\7z.exe', 'a', '-p***************', '-mhe=on', '-sfx', 'C:\\Users\\LB\\AppData\\Local\\Temp\\tmpuiq1bw8i\\archive.exe', '@C:\\PycharmProjects\\Save\\list.txt', '-bso0', '-bsp0']
2025-07-07 22:14:27,969 - arch_7z_spec - INFO - arch_7z_spec:140 - Архивация завершена успешно
2025-07-07 22:14:27,969 - arch_7z_spec - INFO - arch_7z_spec:140 - Архивация завершена успешно
2025-07-07 22:14:27,969 - __main__ - INFO - save_files:69 - Архив успешно создан
2025-07-07 22:14:27,969 - __main__ - INFO - save_files:69 - Архив успешно создан
2025-07-07 22:14:27,969 - yandex_disk - INFO - yandex_disk:51 - Инициализация YandexDisk
2025-07-07 22:14:27,969 - yandex_disk - INFO - yandex_disk:51 - Инициализация YandexDisk
2025-07-07 22:14:27,969 - yandex_disk - INFO - yandex_disk:67 - Получение токена авторизации
2025-07-07 22:14:27,969 - yandex_disk - INFO - yandex_disk:67 - Получение токена авторизации
2025-07-07 22:14:27,970 - __main__ - INFO - save_files:72 - Начало загрузки на Яндекс.Диск
2025-07-07 22:14:27,970 - __main__ - INFO - save_files:72 - Начало загрузки на Яндекс.Диск
2025-07-07 22:14:27,970 - yandex_disk - INFO - yandex_disk:231 - Быстрая загрузка файла C:\Users\LB\AppData\Local\Temp\tmpuiq1bw8i\archive.exe
2025-07-07 22:14:27,970 - yandex_disk - INFO - yandex_disk:231 - Быстрая загрузка файла C:\Users\LB\AppData\Local\Temp\tmpuiq1bw8i\archive.exe
2025-07-07 22:14:27,970 - yandex_disk - INFO - yandex_disk:81 - Генерация имени архива
2025-07-07 22:14:27,970 - yandex_disk - INFO - yandex_disk:81 - Генерация имени архива
2025-07-07 22:14:28,906 - yandex_disk - INFO - yandex_disk:93 - Сгенерировано имя архива: archive_2025_07_07_6.exe
2025-07-07 22:14:28,906 - yandex_disk - INFO - yandex_disk:93 - Сгенерировано имя архива: archive_2025_07_07_6.exe
2025-07-07 22:14:29,880 - yandex_disk - INFO - yandex_disk:237 - Начало загрузки файла C:\Users\LB\AppData\Local\Temp\tmpuiq1bw8i\archive.exe
2025-07-07 22:14:29,880 - yandex_disk - INFO - yandex_disk:237 - Начало загрузки файла C:\Users\LB\AppData\Local\Temp\tmpuiq1bw8i\archive.exe
2025-07-07 22:15:10,030 - yandex_disk - INFO - yandex_disk:242 - Файл C:\Users\LB\AppData\Local\Temp\tmpuiq1bw8i\archive.exe успешно загружен в archive_2025_07_07_6.exe
2025-07-07 22:15:10,030 - yandex_disk - INFO - yandex_disk:242 - Файл C:\Users\LB\AppData\Local\Temp\tmpuiq1bw8i\archive.exe успешно загружен в archive_2025_07_07_6.exe
2025-07-07 22:15:10,031 - __main__ - INFO - save_files:78 - Архив успешно загружен на Яндекс.Диск
2025-07-07 22:15:10,031 - __main__ - INFO - save_files:78 - Архив успешно загружен на Яндекс.Диск
2025-07-07 22:15:10,040 - main - INFO - save_files:152 - Процесс завершен успешно
2025-07-07 22:15:10,040 - main - INFO - save_files:152 - Процесс завершен успешно
2025-07-07 22:20:52,857 - main - INFO - save_files:134 - Запуск приложения резервного копирования
2025-07-07 22:20:52,858 - __main__ - INFO - save_files:22 - Инициализация SaveFiles
2025-07-07 22:20:52,885 - __main__ - INFO - save_files:52 - Начало создания и загрузки архива
2025-07-07 22:20:52,885 - arch_7z_spec - INFO - arch_7z_spec:115 - Запуск архивации: ['C:\\Users\\LB\\Downloads\\7-Zip\\7z.exe', 'a', '-p***************', '-mhe=on', '-sfx', 'C:\\Users\\LB\\AppData\\Local\\Temp\\tmpdfvdpzkz\\archive.exe', '@C:\\PycharmProjects\\Save\\list.txt', '-bso0', '-bsp0']
2025-07-07 22:20:58,148 - arch_7z_spec - INFO - arch_7z_spec:140 - Архивация завершена успешно
2025-07-07 22:20:58,148 - __main__ - INFO - save_files:69 - Архив успешно создан
2025-07-07 22:20:58,148 - yandex_disk - INFO - yandex_disk:51 - Инициализация YandexDisk
2025-07-07 22:20:58,148 - yandex_disk - INFO - yandex_disk:67 - Получение токена авторизации
2025-07-07 22:20:58,153 - __main__ - INFO - save_files:72 - Начало загрузки на Яндекс.Диск
2025-07-07 22:20:58,153 - yandex_disk - INFO - yandex_disk:231 - Быстрая загрузка файла C:\Users\LB\AppData\Local\Temp\tmpdfvdpzkz\archive.exe
2025-07-07 22:20:58,153 - yandex_disk - INFO - yandex_disk:81 - Генерация имени архива
2025-07-07 22:21:00,359 - yandex_disk - INFO - yandex_disk:93 - Сгенерировано имя архива: archive_2025_07_07_7.exe
2025-07-07 22:21:01,359 - yandex_disk - INFO - yandex_disk:237 - Начало загрузки файла C:\Users\LB\AppData\Local\Temp\tmpdfvdpzkz\archive.exe
2025-07-07 22:21:30,369 - yandex_disk - INFO - yandex_disk:242 - Файл C:\Users\LB\AppData\Local\Temp\tmpdfvdpzkz\archive.exe успешно загружен в archive_2025_07_07_7.exe
2025-07-07 22:21:30,370 - __main__ - INFO - save_files:78 - Архив успешно загружен на Яндекс.Диск
2025-07-07 22:21:30,380 - main - INFO - save_files:139 - Процесс завершен успешно
2025-07-07 22:21:30,380 - main - INFO - save_files:147 - Запуск приложения резервного копирования
2025-07-07 22:21:30,380 - main - INFO - save_files:147 - Запуск приложения резервного копирования
2025-07-07 22:21:30,381 - __main__ - INFO - save_files:22 - Инициализация SaveFiles
2025-07-07 22:21:30,381 - __main__ - INFO - save_files:22 - Инициализация SaveFiles
2025-07-07 22:21:30,398 - __main__ - INFO - save_files:52 - Начало создания и загрузки архива
2025-07-07 22:21:30,398 - __main__ - INFO - save_files:52 - Начало создания и загрузки архива
2025-07-07 22:21:30,399 - arch_7z_spec - INFO - arch_7z_spec:115 - Запуск архивации: ['C:\\Users\\LB\\Downloads\\7-Zip\\7z.exe', 'a', '-p***************', '-mhe=on', '-sfx', 'C:\\Users\\LB\\AppData\\Local\\Temp\\tmpg7vbe9gu\\archive.exe', '@C:\\PycharmProjects\\Save\\list.txt', '-bso0', '-bsp0']
2025-07-07 22:21:30,399 - arch_7z_spec - INFO - arch_7z_spec:115 - Запуск архивации: ['C:\\Users\\LB\\Downloads\\7-Zip\\7z.exe', 'a', '-p***************', '-mhe=on', '-sfx', 'C:\\Users\\LB\\AppData\\Local\\Temp\\tmpg7vbe9gu\\archive.exe', '@C:\\PycharmProjects\\Save\\list.txt', '-bso0', '-bsp0']
2025-07-07 22:21:34,808 - arch_7z_spec - INFO - arch_7z_spec:140 - Архивация завершена успешно
2025-07-07 22:21:34,808 - arch_7z_spec - INFO - arch_7z_spec:140 - Архивация завершена успешно
2025-07-07 22:21:34,808 - __main__ - INFO - save_files:69 - Архив успешно создан
2025-07-07 22:21:34,808 - __main__ - INFO - save_files:69 - Архив успешно создан
2025-07-07 22:21:34,808 - yandex_disk - INFO - yandex_disk:51 - Инициализация YandexDisk
2025-07-07 22:21:34,808 - yandex_disk - INFO - yandex_disk:51 - Инициализация YandexDisk
2025-07-07 22:21:34,808 - yandex_disk - INFO - yandex_disk:67 - Получение токена авторизации
2025-07-07 22:21:34,808 - yandex_disk - INFO - yandex_disk:67 - Получение токена авторизации
2025-07-07 22:21:34,809 - __main__ - INFO - save_files:72 - Начало загрузки на Яндекс.Диск
2025-07-07 22:21:34,809 - __main__ - INFO - save_files:72 - Начало загрузки на Яндекс.Диск
2025-07-07 22:21:34,809 - yandex_disk - INFO - yandex_disk:231 - Быстрая загрузка файла C:\Users\LB\AppData\Local\Temp\tmpg7vbe9gu\archive.exe
2025-07-07 22:21:34,809 - yandex_disk - INFO - yandex_disk:231 - Быстрая загрузка файла C:\Users\LB\AppData\Local\Temp\tmpg7vbe9gu\archive.exe
2025-07-07 22:21:34,810 - yandex_disk - INFO - yandex_disk:81 - Генерация имени архива
2025-07-07 22:21:34,810 - yandex_disk - INFO - yandex_disk:81 - Генерация имени архива
2025-07-07 22:21:35,608 - yandex_disk - INFO - yandex_disk:93 - Сгенерировано имя архива: archive_2025_07_07_8.exe
2025-07-07 22:21:35,608 - yandex_disk - INFO - yandex_disk:93 - Сгенерировано имя архива: archive_2025_07_07_8.exe
2025-07-07 22:21:36,472 - yandex_disk - INFO - yandex_disk:237 - Начало загрузки файла C:\Users\LB\AppData\Local\Temp\tmpg7vbe9gu\archive.exe
2025-07-07 22:21:36,472 - yandex_disk - INFO - yandex_disk:237 - Начало загрузки файла C:\Users\LB\AppData\Local\Temp\tmpg7vbe9gu\archive.exe
2025-07-07 22:22:05,405 - yandex_disk - INFO - yandex_disk:242 - Файл C:\Users\LB\AppData\Local\Temp\tmpg7vbe9gu\archive.exe успешно загружен в archive_2025_07_07_8.exe
2025-07-07 22:22:05,405 - yandex_disk - INFO - yandex_disk:242 - Файл C:\Users\LB\AppData\Local\Temp\tmpg7vbe9gu\archive.exe успешно загружен в archive_2025_07_07_8.exe
2025-07-07 22:22:05,405 - __main__ - INFO - save_files:78 - Архив успешно загружен на Яндекс.Диск
2025-07-07 22:22:05,405 - __main__ - INFO - save_files:78 - Архив успешно загружен на Яндекс.Диск
2025-07-07 22:22:05,411 - main - INFO - save_files:152 - Процесс завершен успешно
2025-07-07 22:22:05,411 - main - INFO - save_files:152 - Процесс завершен успешно
2025-07-07 22:22:52,530 - main - INFO - save_files:134 - Запуск приложения резервного копирования
2025-07-07 22:22:52,531 - __main__ - INFO - save_files:22 - Инициализация SaveFiles
2025-07-07 22:22:52,551 - __main__ - INFO - save_files:52 - Начало создания и загрузки архива
2025-07-07 22:22:52,551 - arch_7z_spec - INFO - arch_7z_spec:115 - Запуск архивации: ['C:\\Users\\LB\\Downloads\\7-Zip\\7z.exe', 'a', '-p***************', '-mhe=on', '-sfx', 'C:\\Users\\LB\\AppData\\Local\\Temp\\tmpqet7w5a9\\archive.exe', '@C:\\PycharmProjects\\Save\\list.txt', '-bso0', '-bsp0']
2025-07-07 22:22:57,602 - arch_7z_spec - INFO - arch_7z_spec:140 - Архивация завершена успешно
2025-07-07 22:22:57,602 - __main__ - INFO - save_files:69 - Архив успешно создан
2025-07-07 22:22:57,602 - yandex_disk - INFO - yandex_disk:51 - Инициализация YandexDisk
2025-07-07 22:22:57,602 - yandex_disk - INFO - yandex_disk:67 - Получение токена авторизации
2025-07-07 22:22:57,603 - __main__ - INFO - save_files:72 - Начало загрузки на Яндекс.Диск
2025-07-07 22:22:57,603 - yandex_disk - INFO - yandex_disk:231 - Быстрая загрузка файла C:\Users\LB\AppData\Local\Temp\tmpqet7w5a9\archive.exe
2025-07-07 22:22:57,603 - yandex_disk - INFO - yandex_disk:81 - Генерация имени архива
2025-07-07 22:22:58,440 - yandex_disk - INFO - yandex_disk:93 - Сгенерировано имя архива: archive_2025_07_07_9.exe
2025-07-07 22:22:59,453 - yandex_disk - INFO - yandex_disk:237 - Начало загрузки файла C:\Users\LB\AppData\Local\Temp\tmpqet7w5a9\archive.exe
2025-07-07 22:23:50,231 - yandex_disk - INFO - yandex_disk:242 - Файл C:\Users\LB\AppData\Local\Temp\tmpqet7w5a9\archive.exe успешно загружен в archive_2025_07_07_9.exe
2025-07-07 22:23:50,231 - __main__ - INFO - save_files:78 - Архив успешно загружен на Яндекс.Диск
2025-07-07 22:23:50,238 - main - INFO - save_files:139 - Процесс завершен успешно
2025-07-08 10:09:32,122 - main - INFO - save_files:156 - Запуск приложения резервного копирования
2025-07-08 10:09:32,123 - __main__ - INFO - save_files:22 - Инициализация SaveFiles
2025-07-08 10:09:32,154 - __main__ - INFO - save_files:50 - Начало создания и загрузки архива
2025-07-08 10:09:32,154 - arch_7z_spec - INFO - arch_7z_spec:115 - Запуск архивации: ['C:\\Users\\LB\\Downloads\\7-Zip\\7z.exe', 'a', '-p***************', '-mhe=on', '-sfx', 'C:\\Users\\LB\\AppData\\Local\\Temp\\tmpgxgz2sqf\\archive.exe', '@C:\\PycharmProjects\\Save\\list.txt', '-bso0', '-bsp0']
2025-07-08 10:09:36,852 - arch_7z_spec - INFO - arch_7z_spec:140 - Архивация завершена успешно
2025-07-08 10:09:36,852 - __main__ - INFO - save_files:74 - Архив успешно создан
2025-07-08 10:09:36,852 - yandex_disk - INFO - yandex_disk:51 - Инициализация YandexDisk
2025-07-08 10:09:36,852 - yandex_disk - INFO - yandex_disk:67 - Получение токена авторизации
2025-07-08 10:09:36,856 - __main__ - INFO - save_files:79 - Начало загрузки на Яндекс.Диск
2025-07-08 10:09:36,856 - yandex_disk - INFO - yandex_disk:231 - Быстрая загрузка файла C:\Users\LB\AppData\Local\Temp\tmpgxgz2sqf\archive.exe
2025-07-08 10:09:36,856 - yandex_disk - INFO - yandex_disk:81 - Генерация имени архива
2025-07-08 10:09:37,739 - yandex_disk - WARNING - yandex_disk:119 - Папка disk:/Архивы не найдена, создаем
2025-07-08 10:09:38,359 - yandex_disk - INFO - yandex_disk:121 - Папка disk:/Архивы создана
2025-07-08 10:09:38,360 - yandex_disk - INFO - yandex_disk:93 - Сгенерировано имя архива: archive_2025_07_08_1.exe
2025-07-08 10:09:39,322 - yandex_disk - INFO - yandex_disk:237 - Начало быстрой загрузки файла C:\Users\LB\AppData\Local\Temp\tmpgxgz2sqf\archive.exe
2025-07-08 10:10:20,180 - yandex_disk - INFO - yandex_disk:242 - Файл C:\Users\LB\AppData\Local\Temp\tmpgxgz2sqf\archive.exe успешно загружен в archive_2025_07_08_1.exe
2025-07-08 10:10:20,181 - __main__ - INFO - save_files:85 - Архив успешно загружен на Яндекс.Диск
2025-07-08 10:10:20,194 - main - INFO - save_files:161 - Процесс завершен успешно
2025-07-08 11:15:24,557 - main - INFO - save_files:156 - Запуск приложения резервного копирования
2025-07-08 11:15:24,557 - __main__ - INFO - save_files:22 - Инициализация SaveFiles
2025-07-08 11:15:24,579 - __main__ - INFO - save_files:50 - Начало создания и загрузки архива
2025-07-08 11:15:24,579 - arch_7z_spec - INFO - arch_7z_spec:115 - Запуск архивации: ['C:\\Users\\LB\\Downloads\\7-Zip\\7z.exe', 'a', '-p***************', '-mhe=on', '-sfx', 'C:\\Users\\LB\\AppData\\Local\\Temp\\tmp8q3s1h2n\\archive.exe', '@C:\\PycharmProjects\\Save\\list.txt', '-bso0', '-bsp0']
2025-07-08 11:15:25,376 - main - INFO - save_files:156 - Запуск приложения резервного копирования
2025-07-08 11:15:25,376 - __main__ - INFO - save_files:22 - Инициализация SaveFiles
2025-07-08 11:15:25,399 - __main__ - INFO - save_files:50 - Начало создания и загрузки архива
2025-07-08 11:15:25,400 - arch_7z_spec - INFO - arch_7z_spec:115 - Запуск архивации: ['C:\\Users\\LB\\Downloads\\7-Zip\\7z.exe', 'a', '-p***************', '-mhe=on', '-sfx', 'C:\\Users\\LB\\AppData\\Local\\Temp\\tmphq7xf4_k\\archive.exe', '@C:\\PycharmProjects\\Save\\list.txt', '-bso0', '-bsp0']
2025-07-08 11:15:33,039 - main - INFO - save_files:156 - Запуск приложения резервного копирования
2025-07-08 11:15:33,039 - __main__ - INFO - save_files:22 - Инициализация SaveFiles
2025-07-08 11:15:33,059 - __main__ - INFO - save_files:50 - Начало создания и загрузки архива
2025-07-08 11:15:33,059 - arch_7z_spec - INFO - arch_7z_spec:115 - Запуск архивации: ['C:\\Users\\LB\\Downloads\\7-Zip\\7z.exe', 'a', '-p***************', '-mhe=on', '-sfx', 'C:\\Users\\LB\\AppData\\Local\\Temp\\tmp3n29gyq2\\archive.exe', '@C:\\PycharmProjects\\Save\\list.txt', '-bso0', '-bsp0']
2025-07-08 11:15:37,439 - arch_7z_spec - INFO - arch_7z_spec:140 - Архивация завершена успешно
2025-07-08 11:15:37,439 - __main__ - INFO - save_files:74 - Архив успешно создан
2025-07-08 11:15:37,439 - yandex_disk - INFO - yandex_disk:64 - Инициализация YandexDisk
2025-07-08 11:15:37,440 - yandex_disk - INFO - yandex_disk:66 - Получение токена авторизации
2025-07-08 11:15:37,441 - __main__ - INFO - save_files:79 - Начало загрузки на Яндекс.Диск
2025-07-08 11:15:37,441 - yandex_disk - INFO - yandex_disk:235 - Быстрая загрузка файла C:\Users\LB\AppData\Local\Temp\tmp3n29gyq2\archive.exe
2025-07-08 11:15:37,441 - yandex_disk - INFO - yandex_disk:84 - Генерация имени архива
2025-07-08 11:16:28,680 - yandex_disk - ERROR - yandex_disk:126 - Ошибка получения списка файлов: HTTPSConnectionPool(host='cloud-api.yandex.net', port=443): Max retries exceeded with url: /v1/disk/resources?path=disk%3A%2F%D0%90%D1%80%D1%85%D0%B8%D0%B2%D1%8B&limit=500&fields=type%2C_embedded%2C_embedded.offset%2C_embedded.limit%2C_embedded.total%2C_embedded.items (Caused by ConnectTimeoutError(<urllib3.connection.HTTPSConnection object at 0x0000029AB012B4D0>, 'Connection to cloud-api.yandex.net timed out. (connect timeout=10.0)'))
Traceback (most recent call last):
  File "C:\PycharmProjects\Save\.venv\Lib\site-packages\urllib3\connection.py", line 198, in _new_conn
    sock = connection.create_connection(
        (self._dns_host, self.port),
    ...<2 lines>...
        socket_options=self.socket_options,
    )
  File "C:\PycharmProjects\Save\.venv\Lib\site-packages\urllib3\util\connection.py", line 85, in create_connection
    raise err
  File "C:\PycharmProjects\Save\.venv\Lib\site-packages\urllib3\util\connection.py", line 73, in create_connection
    sock.connect(sa)
    ~~~~~~~~~~~~^^^^
TimeoutError: timed out

The above exception was the direct cause of the following exception:

Traceback (most recent call last):
  File "C:\PycharmProjects\Save\.venv\Lib\site-packages\urllib3\connectionpool.py", line 787, in urlopen
    response = self._make_request(
        conn,
    ...<10 lines>...
        **response_kw,
    )
  File "C:\PycharmProjects\Save\.venv\Lib\site-packages\urllib3\connectionpool.py", line 488, in _make_request
    raise new_e
  File "C:\PycharmProjects\Save\.venv\Lib\site-packages\urllib3\connectionpool.py", line 464, in _make_request
    self._validate_conn(conn)
    ~~~~~~~~~~~~~~~~~~~^^^^^^
  File "C:\PycharmProjects\Save\.venv\Lib\site-packages\urllib3\connectionpool.py", line 1093, in _validate_conn
    conn.connect()
    ~~~~~~~~~~~~^^
  File "C:\PycharmProjects\Save\.venv\Lib\site-packages\urllib3\connection.py", line 704, in connect
    self.sock = sock = self._new_conn()
                       ~~~~~~~~~~~~~~^^
  File "C:\PycharmProjects\Save\.venv\Lib\site-packages\urllib3\connection.py", line 207, in _new_conn
    raise ConnectTimeoutError(
    ...<2 lines>...
    ) from e
urllib3.exceptions.ConnectTimeoutError: (<urllib3.connection.HTTPSConnection object at 0x0000029AB012B4D0>, 'Connection to cloud-api.yandex.net timed out. (connect timeout=10.0)')

The above exception was the direct cause of the following exception:

Traceback (most recent call last):
  File "C:\PycharmProjects\Save\.venv\Lib\site-packages\requests\adapters.py", line 667, in send
    resp = conn.urlopen(
        method=request.method,
    ...<9 lines>...
        chunked=chunked,
    )
  File "C:\PycharmProjects\Save\.venv\Lib\site-packages\urllib3\connectionpool.py", line 841, in urlopen
    retries = retries.increment(
        method, url, error=new_e, _pool=self, _stacktrace=sys.exc_info()[2]
    )
  File "C:\PycharmProjects\Save\.venv\Lib\site-packages\urllib3\util\retry.py", line 519, in increment
    raise MaxRetryError(_pool, url, reason) from reason  # type: ignore[arg-type]
    ^^^^^^^^^^^^^^^^^^^^^^^^^^^^^^^^^^^^^^^^^^^^^^^^^^^
urllib3.exceptions.MaxRetryError: HTTPSConnectionPool(host='cloud-api.yandex.net', port=443): Max retries exceeded with url: /v1/disk/resources?path=disk%3A%2F%D0%90%D1%80%D1%85%D0%B8%D0%B2%D1%8B&limit=500&fields=type%2C_embedded%2C_embedded.offset%2C_embedded.limit%2C_embedded.total%2C_embedded.items (Caused by ConnectTimeoutError(<urllib3.connection.HTTPSConnection object at 0x0000029AB012B4D0>, 'Connection to cloud-api.yandex.net timed out. (connect timeout=10.0)'))

During handling of the above exception, another exception occurred:

Traceback (most recent call last):
  File "C:\PycharmProjects\Save\.venv\Lib\site-packages\yadisk\sessions\requests_session.py", line 163, in send_request
    self.requests_session.request(method, url, **converted_kwargs)
    ~~~~~~~~~~~~~~~~~~~~~~~~~~~~~^^^^^^^^^^^^^^^^^^^^^^^^^^^^^^^^^
  File "C:\PycharmProjects\Save\.venv\Lib\site-packages\requests\sessions.py", line 589, in request
    resp = self.send(prep, **send_kwargs)
  File "C:\PycharmProjects\Save\.venv\Lib\site-packages\requests\sessions.py", line 703, in send
    r = adapter.send(request, **kwargs)
  File "C:\PycharmProjects\Save\.venv\Lib\site-packages\requests\adapters.py", line 688, in send
    raise ConnectTimeout(e, request=request)
requests.exceptions.ConnectTimeout: HTTPSConnectionPool(host='cloud-api.yandex.net', port=443): Max retries exceeded with url: /v1/disk/resources?path=disk%3A%2F%D0%90%D1%80%D1%85%D0%B8%D0%B2%D1%8B&limit=500&fields=type%2C_embedded%2C_embedded.offset%2C_embedded.limit%2C_embedded.total%2C_embedded.items (Caused by ConnectTimeoutError(<urllib3.connection.HTTPSConnection object at 0x0000029AB012B4D0>, 'Connection to cloud-api.yandex.net timed out. (connect timeout=10.0)'))

The above exception was the direct cause of the following exception:

Traceback (most recent call last):
  File "C:\PycharmProjects\Save\SRC\yandex_disk.py", line 109, in _get_file_nums
    for item in self.disk.listdir(self.archive_path):
                ~~~~~~~~~~~~~~~~~^^^^^^^^^^^^^^^^^^^
  File "C:\PycharmProjects\Save\.venv\Lib\site-packages\yadisk\_client.py", line 133, in _listdir
    result = get_meta_function(path, _then=_validate_listdir_response, **kwargs)
  File "C:\PycharmProjects\Save\.venv\Lib\site-packages\yadisk\_client.py", line 773, in get_meta
    return GetMetaRequest(self.session, path, **kwargs).send(yadisk=self, then=_then)
           ~~~~~~~~~~~~~~~~~~~~~~~~~~~~~~~~~~~~~~~~~~~~~~~~~^^^^^^^^^^^^^^^^^^^^^^^^^
  File "C:\PycharmProjects\Save\.venv\Lib\site-packages\yadisk\_api\api_request.py", line 241, in send
    return auto_retry(
        self._attempt,
    ...<3 lines>...
        retry_on=self.retry_on
    )
  File "C:\PycharmProjects\Save\.venv\Lib\site-packages\yadisk\utils.py", line 198, in auto_retry
    return func(*args, **kwargs)
  File "C:\PycharmProjects\Save\.venv\Lib\site-packages\yadisk\_api\api_request.py", line 157, in _attempt
    response = session.send_request(self.method, self.url, **kwargs)
  File "C:\PycharmProjects\Save\.venv\Lib\site-packages\yadisk\sessions\requests_session.py", line 166, in send_request
    raise convert_requests_exception(e) from e
yadisk.exceptions.RequestTimeoutError: HTTPSConnectionPool(host='cloud-api.yandex.net', port=443): Max retries exceeded with url: /v1/disk/resources?path=disk%3A%2F%D0%90%D1%80%D1%85%D0%B8%D0%B2%D1%8B&limit=500&fields=type%2C_embedded%2C_embedded.offset%2C_embedded.limit%2C_embedded.total%2C_embedded.items (Caused by ConnectTimeoutError(<urllib3.connection.HTTPSConnection object at 0x0000029AB012B4D0>, 'Connection to cloud-api.yandex.net timed out. (connect timeout=10.0)'))
Got the error after 3 retry attempts
2025-07-08 11:16:28,711 - __main__ - ERROR - save_files:56 - Критическая ошибка в make_and_write_archive HTTPSConnectionPool(host='cloud-api.yandex.net', port=443): Max retries exceeded with url: /v1/disk/resources?path=disk%3A%2F%D0%90%D1%80%D1%85%D0%B8%D0%B2%D1%8B&limit=500&fields=type%2C_embedded%2C_embedded.offset%2C_embedded.limit%2C_embedded.total%2C_embedded.items (Caused by ConnectTimeoutError(<urllib3.connection.HTTPSConnection object at 0x0000029AB012B4D0>, 'Connection to cloud-api.yandex.net timed out. (connect timeout=10.0)'))
Traceback (most recent call last):
  File "C:\PycharmProjects\Save\.venv\Lib\site-packages\urllib3\connection.py", line 198, in _new_conn
    sock = connection.create_connection(
        (self._dns_host, self.port),
    ...<2 lines>...
        socket_options=self.socket_options,
    )
  File "C:\PycharmProjects\Save\.venv\Lib\site-packages\urllib3\util\connection.py", line 85, in create_connection
    raise err
  File "C:\PycharmProjects\Save\.venv\Lib\site-packages\urllib3\util\connection.py", line 73, in create_connection
    sock.connect(sa)
    ~~~~~~~~~~~~^^^^
TimeoutError: timed out

The above exception was the direct cause of the following exception:

Traceback (most recent call last):
  File "C:\PycharmProjects\Save\.venv\Lib\site-packages\urllib3\connectionpool.py", line 787, in urlopen
    response = self._make_request(
        conn,
    ...<10 lines>...
        **response_kw,
    )
  File "C:\PycharmProjects\Save\.venv\Lib\site-packages\urllib3\connectionpool.py", line 488, in _make_request
    raise new_e
  File "C:\PycharmProjects\Save\.venv\Lib\site-packages\urllib3\connectionpool.py", line 464, in _make_request
    self._validate_conn(conn)
    ~~~~~~~~~~~~~~~~~~~^^^^^^
  File "C:\PycharmProjects\Save\.venv\Lib\site-packages\urllib3\connectionpool.py", line 1093, in _validate_conn
    conn.connect()
    ~~~~~~~~~~~~^^
  File "C:\PycharmProjects\Save\.venv\Lib\site-packages\urllib3\connection.py", line 704, in connect
    self.sock = sock = self._new_conn()
                       ~~~~~~~~~~~~~~^^
  File "C:\PycharmProjects\Save\.venv\Lib\site-packages\urllib3\connection.py", line 207, in _new_conn
    raise ConnectTimeoutError(
    ...<2 lines>...
    ) from e
urllib3.exceptions.ConnectTimeoutError: (<urllib3.connection.HTTPSConnection object at 0x0000029AB012B4D0>, 'Connection to cloud-api.yandex.net timed out. (connect timeout=10.0)')

The above exception was the direct cause of the following exception:

Traceback (most recent call last):
  File "C:\PycharmProjects\Save\.venv\Lib\site-packages\requests\adapters.py", line 667, in send
    resp = conn.urlopen(
        method=request.method,
    ...<9 lines>...
        chunked=chunked,
    )
  File "C:\PycharmProjects\Save\.venv\Lib\site-packages\urllib3\connectionpool.py", line 841, in urlopen
    retries = retries.increment(
        method, url, error=new_e, _pool=self, _stacktrace=sys.exc_info()[2]
    )
  File "C:\PycharmProjects\Save\.venv\Lib\site-packages\urllib3\util\retry.py", line 519, in increment
    raise MaxRetryError(_pool, url, reason) from reason  # type: ignore[arg-type]
    ^^^^^^^^^^^^^^^^^^^^^^^^^^^^^^^^^^^^^^^^^^^^^^^^^^^
urllib3.exceptions.MaxRetryError: HTTPSConnectionPool(host='cloud-api.yandex.net', port=443): Max retries exceeded with url: /v1/disk/resources?path=disk%3A%2F%D0%90%D1%80%D1%85%D0%B8%D0%B2%D1%8B&limit=500&fields=type%2C_embedded%2C_embedded.offset%2C_embedded.limit%2C_embedded.total%2C_embedded.items (Caused by ConnectTimeoutError(<urllib3.connection.HTTPSConnection object at 0x0000029AB012B4D0>, 'Connection to cloud-api.yandex.net timed out. (connect timeout=10.0)'))

During handling of the above exception, another exception occurred:

Traceback (most recent call last):
  File "C:\PycharmProjects\Save\.venv\Lib\site-packages\yadisk\sessions\requests_session.py", line 163, in send_request
    self.requests_session.request(method, url, **converted_kwargs)
    ~~~~~~~~~~~~~~~~~~~~~~~~~~~~~^^^^^^^^^^^^^^^^^^^^^^^^^^^^^^^^^
  File "C:\PycharmProjects\Save\.venv\Lib\site-packages\requests\sessions.py", line 589, in request
    resp = self.send(prep, **send_kwargs)
  File "C:\PycharmProjects\Save\.venv\Lib\site-packages\requests\sessions.py", line 703, in send
    r = adapter.send(request, **kwargs)
  File "C:\PycharmProjects\Save\.venv\Lib\site-packages\requests\adapters.py", line 688, in send
    raise ConnectTimeout(e, request=request)
requests.exceptions.ConnectTimeout: HTTPSConnectionPool(host='cloud-api.yandex.net', port=443): Max retries exceeded with url: /v1/disk/resources?path=disk%3A%2F%D0%90%D1%80%D1%85%D0%B8%D0%B2%D1%8B&limit=500&fields=type%2C_embedded%2C_embedded.offset%2C_embedded.limit%2C_embedded.total%2C_embedded.items (Caused by ConnectTimeoutError(<urllib3.connection.HTTPSConnection object at 0x0000029AB012B4D0>, 'Connection to cloud-api.yandex.net timed out. (connect timeout=10.0)'))

The above exception was the direct cause of the following exception:

Traceback (most recent call last):
  File "C:\PycharmProjects\Save\SRC\save_files.py", line 54, in make_and_write_archive
    self.upload_to_yandex_disk(archive_path)
    ~~~~~~~~~~~~~~~~~~~~~~~~~~^^^^^^^^^^^^^^
  File "C:\PycharmProjects\Save\SRC\save_files.py", line 81, in upload_to_yandex_disk
    if not yandex_disk.write_archive_fast(archive_path):
           ~~~~~~~~~~~~~~~~~~~~~~~~~~~~~~^^^^^^^^^^^^^^
  File "C:\PycharmProjects\Save\SRC\yandex_disk.py", line 236, in write_archive_fast
    upload_url, remote_path = self.get_file_download_URL()
                              ~~~~~~~~~~~~~~~~~~~~~~~~~~^^
  File "C:\PycharmProjects\Save\SRC\yandex_disk.py", line 313, in get_file_download_URL
    archive_name = self.create_archive_name()
  File "C:\PycharmProjects\Save\SRC\yandex_disk.py", line 86, in create_archive_name
    file_nums = self._get_file_nums()
  File "C:\PycharmProjects\Save\SRC\yandex_disk.py", line 109, in _get_file_nums
    for item in self.disk.listdir(self.archive_path):
                ~~~~~~~~~~~~~~~~~^^^^^^^^^^^^^^^^^^^
  File "C:\PycharmProjects\Save\.venv\Lib\site-packages\yadisk\_client.py", line 133, in _listdir
    result = get_meta_function(path, _then=_validate_listdir_response, **kwargs)
  File "C:\PycharmProjects\Save\.venv\Lib\site-packages\yadisk\_client.py", line 773, in get_meta
    return GetMetaRequest(self.session, path, **kwargs).send(yadisk=self, then=_then)
           ~~~~~~~~~~~~~~~~~~~~~~~~~~~~~~~~~~~~~~~~~~~~~~~~~^^^^^^^^^^^^^^^^^^^^^^^^^
  File "C:\PycharmProjects\Save\.venv\Lib\site-packages\yadisk\_api\api_request.py", line 241, in send
    return auto_retry(
        self._attempt,
    ...<3 lines>...
        retry_on=self.retry_on
    )
  File "C:\PycharmProjects\Save\.venv\Lib\site-packages\yadisk\utils.py", line 198, in auto_retry
    return func(*args, **kwargs)
  File "C:\PycharmProjects\Save\.venv\Lib\site-packages\yadisk\_api\api_request.py", line 157, in _attempt
    response = session.send_request(self.method, self.url, **kwargs)
  File "C:\PycharmProjects\Save\.venv\Lib\site-packages\yadisk\sessions\requests_session.py", line 166, in send_request
    raise convert_requests_exception(e) from e
yadisk.exceptions.RequestTimeoutError: HTTPSConnectionPool(host='cloud-api.yandex.net', port=443): Max retries exceeded with url: /v1/disk/resources?path=disk%3A%2F%D0%90%D1%80%D1%85%D0%B8%D0%B2%D1%8B&limit=500&fields=type%2C_embedded%2C_embedded.offset%2C_embedded.limit%2C_embedded.total%2C_embedded.items (Caused by ConnectTimeoutError(<urllib3.connection.HTTPSConnection object at 0x0000029AB012B4D0>, 'Connection to cloud-api.yandex.net timed out. (connect timeout=10.0)'))
Got the error after 3 retry attempts
2025-07-08 11:16:28,716 - main - ERROR - save_files:164 - Критическая ошибка при формировании или записи архива в облако
Traceback (most recent call last):
  File "C:\PycharmProjects\Save\.venv\Lib\site-packages\urllib3\connection.py", line 198, in _new_conn
    sock = connection.create_connection(
        (self._dns_host, self.port),
    ...<2 lines>...
        socket_options=self.socket_options,
    )
  File "C:\PycharmProjects\Save\.venv\Lib\site-packages\urllib3\util\connection.py", line 85, in create_connection
    raise err
  File "C:\PycharmProjects\Save\.venv\Lib\site-packages\urllib3\util\connection.py", line 73, in create_connection
    sock.connect(sa)
    ~~~~~~~~~~~~^^^^
TimeoutError: timed out

The above exception was the direct cause of the following exception:

Traceback (most recent call last):
  File "C:\PycharmProjects\Save\.venv\Lib\site-packages\urllib3\connectionpool.py", line 787, in urlopen
    response = self._make_request(
        conn,
    ...<10 lines>...
        **response_kw,
    )
  File "C:\PycharmProjects\Save\.venv\Lib\site-packages\urllib3\connectionpool.py", line 488, in _make_request
    raise new_e
  File "C:\PycharmProjects\Save\.venv\Lib\site-packages\urllib3\connectionpool.py", line 464, in _make_request
    self._validate_conn(conn)
    ~~~~~~~~~~~~~~~~~~~^^^^^^
  File "C:\PycharmProjects\Save\.venv\Lib\site-packages\urllib3\connectionpool.py", line 1093, in _validate_conn
    conn.connect()
    ~~~~~~~~~~~~^^
  File "C:\PycharmProjects\Save\.venv\Lib\site-packages\urllib3\connection.py", line 704, in connect
    self.sock = sock = self._new_conn()
                       ~~~~~~~~~~~~~~^^
  File "C:\PycharmProjects\Save\.venv\Lib\site-packages\urllib3\connection.py", line 207, in _new_conn
    raise ConnectTimeoutError(
    ...<2 lines>...
    ) from e
urllib3.exceptions.ConnectTimeoutError: (<urllib3.connection.HTTPSConnection object at 0x0000029AB012B4D0>, 'Connection to cloud-api.yandex.net timed out. (connect timeout=10.0)')

The above exception was the direct cause of the following exception:

Traceback (most recent call last):
  File "C:\PycharmProjects\Save\.venv\Lib\site-packages\requests\adapters.py", line 667, in send
    resp = conn.urlopen(
        method=request.method,
    ...<9 lines>...
        chunked=chunked,
    )
  File "C:\PycharmProjects\Save\.venv\Lib\site-packages\urllib3\connectionpool.py", line 841, in urlopen
    retries = retries.increment(
        method, url, error=new_e, _pool=self, _stacktrace=sys.exc_info()[2]
    )
  File "C:\PycharmProjects\Save\.venv\Lib\site-packages\urllib3\util\retry.py", line 519, in increment
    raise MaxRetryError(_pool, url, reason) from reason  # type: ignore[arg-type]
    ^^^^^^^^^^^^^^^^^^^^^^^^^^^^^^^^^^^^^^^^^^^^^^^^^^^
urllib3.exceptions.MaxRetryError: HTTPSConnectionPool(host='cloud-api.yandex.net', port=443): Max retries exceeded with url: /v1/disk/resources?path=disk%3A%2F%D0%90%D1%80%D1%85%D0%B8%D0%B2%D1%8B&limit=500&fields=type%2C_embedded%2C_embedded.offset%2C_embedded.limit%2C_embedded.total%2C_embedded.items (Caused by ConnectTimeoutError(<urllib3.connection.HTTPSConnection object at 0x0000029AB012B4D0>, 'Connection to cloud-api.yandex.net timed out. (connect timeout=10.0)'))

During handling of the above exception, another exception occurred:

Traceback (most recent call last):
  File "C:\PycharmProjects\Save\.venv\Lib\site-packages\yadisk\sessions\requests_session.py", line 163, in send_request
    self.requests_session.request(method, url, **converted_kwargs)
    ~~~~~~~~~~~~~~~~~~~~~~~~~~~~~^^^^^^^^^^^^^^^^^^^^^^^^^^^^^^^^^
  File "C:\PycharmProjects\Save\.venv\Lib\site-packages\requests\sessions.py", line 589, in request
    resp = self.send(prep, **send_kwargs)
  File "C:\PycharmProjects\Save\.venv\Lib\site-packages\requests\sessions.py", line 703, in send
    r = adapter.send(request, **kwargs)
  File "C:\PycharmProjects\Save\.venv\Lib\site-packages\requests\adapters.py", line 688, in send
    raise ConnectTimeout(e, request=request)
requests.exceptions.ConnectTimeout: HTTPSConnectionPool(host='cloud-api.yandex.net', port=443): Max retries exceeded with url: /v1/disk/resources?path=disk%3A%2F%D0%90%D1%80%D1%85%D0%B8%D0%B2%D1%8B&limit=500&fields=type%2C_embedded%2C_embedded.offset%2C_embedded.limit%2C_embedded.total%2C_embedded.items (Caused by ConnectTimeoutError(<urllib3.connection.HTTPSConnection object at 0x0000029AB012B4D0>, 'Connection to cloud-api.yandex.net timed out. (connect timeout=10.0)'))

The above exception was the direct cause of the following exception:

Traceback (most recent call last):
  File "C:\PycharmProjects\Save\SRC\save_files.py", line 160, in <module>
    save_files.make_and_write_archive()
    ~~~~~~~~~~~~~~~~~~~~~~~~~~~~~~~~~^^
  File "C:\PycharmProjects\Save\SRC\save_files.py", line 54, in make_and_write_archive
    self.upload_to_yandex_disk(archive_path)
    ~~~~~~~~~~~~~~~~~~~~~~~~~~^^^^^^^^^^^^^^
  File "C:\PycharmProjects\Save\SRC\save_files.py", line 81, in upload_to_yandex_disk
    if not yandex_disk.write_archive_fast(archive_path):
           ~~~~~~~~~~~~~~~~~~~~~~~~~~~~~~^^^^^^^^^^^^^^
  File "C:\PycharmProjects\Save\SRC\yandex_disk.py", line 236, in write_archive_fast
    upload_url, remote_path = self.get_file_download_URL()
                              ~~~~~~~~~~~~~~~~~~~~~~~~~~^^
  File "C:\PycharmProjects\Save\SRC\yandex_disk.py", line 313, in get_file_download_URL
    archive_name = self.create_archive_name()
  File "C:\PycharmProjects\Save\SRC\yandex_disk.py", line 86, in create_archive_name
    file_nums = self._get_file_nums()
  File "C:\PycharmProjects\Save\SRC\yandex_disk.py", line 109, in _get_file_nums
    for item in self.disk.listdir(self.archive_path):
                ~~~~~~~~~~~~~~~~~^^^^^^^^^^^^^^^^^^^
  File "C:\PycharmProjects\Save\.venv\Lib\site-packages\yadisk\_client.py", line 133, in _listdir
    result = get_meta_function(path, _then=_validate_listdir_response, **kwargs)
  File "C:\PycharmProjects\Save\.venv\Lib\site-packages\yadisk\_client.py", line 773, in get_meta
    return GetMetaRequest(self.session, path, **kwargs).send(yadisk=self, then=_then)
           ~~~~~~~~~~~~~~~~~~~~~~~~~~~~~~~~~~~~~~~~~~~~~~~~~^^^^^^^^^^^^^^^^^^^^^^^^^
  File "C:\PycharmProjects\Save\.venv\Lib\site-packages\yadisk\_api\api_request.py", line 241, in send
    return auto_retry(
        self._attempt,
    ...<3 lines>...
        retry_on=self.retry_on
    )
  File "C:\PycharmProjects\Save\.venv\Lib\site-packages\yadisk\utils.py", line 198, in auto_retry
    return func(*args, **kwargs)
  File "C:\PycharmProjects\Save\.venv\Lib\site-packages\yadisk\_api\api_request.py", line 157, in _attempt
    response = session.send_request(self.method, self.url, **kwargs)
  File "C:\PycharmProjects\Save\.venv\Lib\site-packages\yadisk\sessions\requests_session.py", line 166, in send_request
    raise convert_requests_exception(e) from e
yadisk.exceptions.RequestTimeoutError: HTTPSConnectionPool(host='cloud-api.yandex.net', port=443): Max retries exceeded with url: /v1/disk/resources?path=disk%3A%2F%D0%90%D1%80%D1%85%D0%B8%D0%B2%D1%8B&limit=500&fields=type%2C_embedded%2C_embedded.offset%2C_embedded.limit%2C_embedded.total%2C_embedded.items (Caused by ConnectTimeoutError(<urllib3.connection.HTTPSConnection object at 0x0000029AB012B4D0>, 'Connection to cloud-api.yandex.net timed out. (connect timeout=10.0)'))
Got the error after 3 retry attempts
2025-07-08 11:21:51,507 - main - INFO - save_files:156 - Запуск приложения резервного копирования
2025-07-08 11:21:51,508 - __main__ - INFO - save_files:22 - Инициализация SaveFiles
2025-07-08 11:21:51,536 - __main__ - INFO - save_files:50 - Начало создания и загрузки архива
2025-07-08 11:21:51,536 - arch_7z_spec - INFO - arch_7z_spec:115 - Запуск архивации: ['C:\\Users\\LB\\Downloads\\7-Zip\\7z.exe', 'a', '-p***************', '-mhe=on', '-sfx', 'C:\\Users\\LB\\AppData\\Local\\Temp\\tmprn0u9mlt\\archive.exe', '@C:\\PycharmProjects\\Save\\list.txt', '-bso0', '-bsp0']
2025-07-08 11:21:56,005 - arch_7z_spec - INFO - arch_7z_spec:140 - Архивация завершена успешно
2025-07-08 11:21:56,006 - __main__ - INFO - save_files:74 - Архив успешно создан
2025-07-08 11:21:56,006 - yandex_disk - INFO - yandex_disk:64 - Инициализация YandexDisk
2025-07-08 11:21:56,006 - yandex_disk - INFO - yandex_disk:66 - Получение токена авторизации
2025-07-08 11:21:56,010 - __main__ - INFO - save_files:79 - Начало загрузки на Яндекс.Диск
2025-07-08 11:21:56,010 - yandex_disk - INFO - yandex_disk:235 - Быстрая загрузка файла C:\Users\LB\AppData\Local\Temp\tmprn0u9mlt\archive.exe
2025-07-08 11:21:56,010 - yandex_disk - INFO - yandex_disk:84 - Генерация имени архива
2025-07-08 11:28:38,702 - main - INFO - save_files:156 - Запуск приложения резервного копирования
2025-07-08 11:28:38,702 - __main__ - INFO - save_files:22 - Инициализация SaveFiles
2025-07-08 11:28:38,741 - __main__ - INFO - save_files:50 - Начало создания и загрузки архива
2025-07-08 11:28:38,743 - arch_7z_spec - INFO - arch_7z_spec:115 - Запуск архивации: ['C:\\Users\\LB\\Downloads\\7-Zip\\7z.exe', 'a', '-p***************', '-mhe=on', '-sfx', 'C:\\Users\\LB\\AppData\\Local\\Temp\\tmptnck7b22\\archive.exe', '@C:\\PycharmProjects\\Save\\list.txt', '-bso0', '-bsp0']
2025-07-08 11:28:43,323 - arch_7z_spec - INFO - arch_7z_spec:140 - Архивация завершена успешно
2025-07-08 11:28:43,323 - __main__ - INFO - save_files:74 - Архив успешно создан
2025-07-08 11:28:43,323 - yandex_disk - INFO - yandex_disk:64 - Инициализация YandexDisk
2025-07-08 11:28:43,323 - yandex_disk - INFO - yandex_disk:66 - Получение токена авторизации
2025-07-08 11:28:43,328 - __main__ - INFO - save_files:79 - Начало загрузки на Яндекс.Диск
2025-07-08 11:28:43,328 - yandex_disk - INFO - yandex_disk:235 - Быстрая загрузка файла C:\Users\LB\AppData\Local\Temp\tmptnck7b22\archive.exe
2025-07-08 11:28:43,328 - yandex_disk - INFO - yandex_disk:84 - Генерация имени архива
2025-07-08 11:31:13,620 - main - INFO - save_files:156 - Запуск приложения резервного копирования
2025-07-08 11:31:13,621 - __main__ - INFO - save_files:22 - Инициализация SaveFiles
2025-07-08 11:31:13,642 - __main__ - INFO - save_files:50 - Начало создания и загрузки архива
2025-07-08 11:31:13,643 - arch_7z_spec - INFO - arch_7z_spec:115 - Запуск архивации: ['C:\\Users\\LB\\Downloads\\7-Zip\\7z.exe', 'a', '-p***************', '-mhe=on', '-sfx', 'C:\\Users\\LB\\AppData\\Local\\Temp\\tmpe1tkpq5u\\archive.exe', '@C:\\PycharmProjects\\Save\\list.txt', '-bso0', '-bsp0']
2025-07-08 11:31:18,407 - arch_7z_spec - INFO - arch_7z_spec:140 - Архивация завершена успешно
2025-07-08 11:31:18,407 - __main__ - INFO - save_files:74 - Архив успешно создан
2025-07-08 11:31:18,407 - yandex_disk - INFO - yandex_disk:64 - Инициализация YandexDisk
2025-07-08 11:31:18,407 - yandex_disk - INFO - yandex_disk:66 - Получение токена авторизации
2025-07-08 11:31:18,408 - __main__ - INFO - save_files:79 - Начало загрузки на Яндекс.Диск
2025-07-08 11:31:18,408 - yandex_disk - INFO - yandex_disk:235 - Быстрая загрузка файла C:\Users\LB\AppData\Local\Temp\tmpe1tkpq5u\archive.exe
2025-07-08 11:31:18,408 - yandex_disk - INFO - yandex_disk:84 - Генерация имени архива
2025-07-08 11:32:26,126 - main - INFO - save_files:156 - Запуск приложения резервного копирования
2025-07-08 11:32:26,127 - __main__ - INFO - save_files:22 - Инициализация SaveFiles
2025-07-08 11:32:26,149 - __main__ - INFO - save_files:50 - Начало создания и загрузки архива
2025-07-08 11:32:26,150 - arch_7z_spec - INFO - arch_7z_spec:115 - Запуск архивации: ['C:\\Users\\LB\\Downloads\\7-Zip\\7z.exe', 'a', '-p***************', '-mhe=on', '-sfx', 'C:\\Users\\LB\\AppData\\Local\\Temp\\tmpvn18zxb9\\archive.exe', '@C:\\PycharmProjects\\Save\\list.txt', '-bso0', '-bsp0']
2025-07-08 11:32:31,344 - arch_7z_spec - INFO - arch_7z_spec:140 - Архивация завершена успешно
2025-07-08 11:32:31,344 - __main__ - INFO - save_files:74 - Архив успешно создан
2025-07-08 11:32:31,344 - yandex_disk - INFO - yandex_disk:64 - Инициализация YandexDisk
2025-07-08 11:32:31,344 - yandex_disk - INFO - yandex_disk:66 - Получение токена авторизации
2025-07-08 11:32:31,346 - __main__ - INFO - save_files:79 - Начало загрузки на Яндекс.Диск
2025-07-08 11:32:31,346 - yandex_disk - INFO - yandex_disk:235 - Быстрая загрузка файла C:\Users\LB\AppData\Local\Temp\tmpvn18zxb9\archive.exe
2025-07-08 11:32:31,346 - yandex_disk - INFO - yandex_disk:84 - Генерация имени архива
2025-07-08 11:33:34,897 - yandex_disk - ERROR - yandex_disk:126 - Ошибка получения списка файлов: HTTPSConnectionPool(host='cloud-api.yandex.net', port=443): Max retries exceeded with url: /v1/disk/resources?path=disk%3A%2F%D0%90%D1%80%D1%85%D0%B8%D0%B2%D1%8B&limit=500&fields=type%2C_embedded%2C_embedded.offset%2C_embedded.limit%2C_embedded.total%2C_embedded.items (Caused by ConnectTimeoutError(<urllib3.connection.HTTPSConnection object at 0x00000192A764B4D0>, 'Connection to cloud-api.yandex.net timed out. (connect timeout=10.0)'))
Traceback (most recent call last):
  File "C:\PycharmProjects\Save\.venv\Lib\site-packages\urllib3\connection.py", line 198, in _new_conn
    sock = connection.create_connection(
        (self._dns_host, self.port),
    ...<2 lines>...
        socket_options=self.socket_options,
    )
  File "C:\PycharmProjects\Save\.venv\Lib\site-packages\urllib3\util\connection.py", line 85, in create_connection
    raise err
  File "C:\PycharmProjects\Save\.venv\Lib\site-packages\urllib3\util\connection.py", line 73, in create_connection
    sock.connect(sa)
    ~~~~~~~~~~~~^^^^
TimeoutError: timed out

The above exception was the direct cause of the following exception:

Traceback (most recent call last):
  File "C:\PycharmProjects\Save\.venv\Lib\site-packages\urllib3\connectionpool.py", line 787, in urlopen
    response = self._make_request(
        conn,
    ...<10 lines>...
        **response_kw,
    )
  File "C:\PycharmProjects\Save\.venv\Lib\site-packages\urllib3\connectionpool.py", line 488, in _make_request
    raise new_e
  File "C:\PycharmProjects\Save\.venv\Lib\site-packages\urllib3\connectionpool.py", line 464, in _make_request
    self._validate_conn(conn)
    ~~~~~~~~~~~~~~~~~~~^^^^^^
  File "C:\PycharmProjects\Save\.venv\Lib\site-packages\urllib3\connectionpool.py", line 1093, in _validate_conn
    conn.connect()
    ~~~~~~~~~~~~^^
  File "C:\PycharmProjects\Save\.venv\Lib\site-packages\urllib3\connection.py", line 704, in connect
    self.sock = sock = self._new_conn()
                       ~~~~~~~~~~~~~~^^
  File "C:\PycharmProjects\Save\.venv\Lib\site-packages\urllib3\connection.py", line 207, in _new_conn
    raise ConnectTimeoutError(
    ...<2 lines>...
    ) from e
urllib3.exceptions.ConnectTimeoutError: (<urllib3.connection.HTTPSConnection object at 0x00000192A764B4D0>, 'Connection to cloud-api.yandex.net timed out. (connect timeout=10.0)')

The above exception was the direct cause of the following exception:

Traceback (most recent call last):
  File "C:\PycharmProjects\Save\.venv\Lib\site-packages\requests\adapters.py", line 667, in send
    resp = conn.urlopen(
        method=request.method,
    ...<9 lines>...
        chunked=chunked,
    )
  File "C:\PycharmProjects\Save\.venv\Lib\site-packages\urllib3\connectionpool.py", line 841, in urlopen
    retries = retries.increment(
        method, url, error=new_e, _pool=self, _stacktrace=sys.exc_info()[2]
    )
  File "C:\PycharmProjects\Save\.venv\Lib\site-packages\urllib3\util\retry.py", line 519, in increment
    raise MaxRetryError(_pool, url, reason) from reason  # type: ignore[arg-type]
    ^^^^^^^^^^^^^^^^^^^^^^^^^^^^^^^^^^^^^^^^^^^^^^^^^^^
urllib3.exceptions.MaxRetryError: HTTPSConnectionPool(host='cloud-api.yandex.net', port=443): Max retries exceeded with url: /v1/disk/resources?path=disk%3A%2F%D0%90%D1%80%D1%85%D0%B8%D0%B2%D1%8B&limit=500&fields=type%2C_embedded%2C_embedded.offset%2C_embedded.limit%2C_embedded.total%2C_embedded.items (Caused by ConnectTimeoutError(<urllib3.connection.HTTPSConnection object at 0x00000192A764B4D0>, 'Connection to cloud-api.yandex.net timed out. (connect timeout=10.0)'))

During handling of the above exception, another exception occurred:

Traceback (most recent call last):
  File "C:\PycharmProjects\Save\.venv\Lib\site-packages\yadisk\sessions\requests_session.py", line 163, in send_request
    self.requests_session.request(method, url, **converted_kwargs)
    ~~~~~~~~~~~~~~~~~~~~~~~~~~~~~^^^^^^^^^^^^^^^^^^^^^^^^^^^^^^^^^
  File "C:\PycharmProjects\Save\.venv\Lib\site-packages\requests\sessions.py", line 589, in request
    resp = self.send(prep, **send_kwargs)
  File "C:\PycharmProjects\Save\.venv\Lib\site-packages\requests\sessions.py", line 703, in send
    r = adapter.send(request, **kwargs)
  File "C:\PycharmProjects\Save\.venv\Lib\site-packages\requests\adapters.py", line 688, in send
    raise ConnectTimeout(e, request=request)
requests.exceptions.ConnectTimeout: HTTPSConnectionPool(host='cloud-api.yandex.net', port=443): Max retries exceeded with url: /v1/disk/resources?path=disk%3A%2F%D0%90%D1%80%D1%85%D0%B8%D0%B2%D1%8B&limit=500&fields=type%2C_embedded%2C_embedded.offset%2C_embedded.limit%2C_embedded.total%2C_embedded.items (Caused by ConnectTimeoutError(<urllib3.connection.HTTPSConnection object at 0x00000192A764B4D0>, 'Connection to cloud-api.yandex.net timed out. (connect timeout=10.0)'))

The above exception was the direct cause of the following exception:

Traceback (most recent call last):
  File "C:\PycharmProjects\Save\SRC\yandex_disk.py", line 109, in _get_file_nums
    for item in self.disk.listdir(self.archive_path):
                ~~~~~~~~~~~~~~~~~^^^^^^^^^^^^^^^^^^^
  File "C:\PycharmProjects\Save\.venv\Lib\site-packages\yadisk\_client.py", line 133, in _listdir
    result = get_meta_function(path, _then=_validate_listdir_response, **kwargs)
  File "C:\PycharmProjects\Save\.venv\Lib\site-packages\yadisk\_client.py", line 773, in get_meta
    return GetMetaRequest(self.session, path, **kwargs).send(yadisk=self, then=_then)
           ~~~~~~~~~~~~~~~~~~~~~~~~~~~~~~~~~~~~~~~~~~~~~~~~~^^^^^^^^^^^^^^^^^^^^^^^^^
  File "C:\PycharmProjects\Save\.venv\Lib\site-packages\yadisk\_api\api_request.py", line 241, in send
    return auto_retry(
        self._attempt,
    ...<3 lines>...
        retry_on=self.retry_on
    )
  File "C:\PycharmProjects\Save\.venv\Lib\site-packages\yadisk\utils.py", line 198, in auto_retry
    return func(*args, **kwargs)
  File "C:\PycharmProjects\Save\.venv\Lib\site-packages\yadisk\_api\api_request.py", line 157, in _attempt
    response = session.send_request(self.method, self.url, **kwargs)
  File "C:\PycharmProjects\Save\.venv\Lib\site-packages\yadisk\sessions\requests_session.py", line 166, in send_request
    raise convert_requests_exception(e) from e
yadisk.exceptions.RequestTimeoutError: HTTPSConnectionPool(host='cloud-api.yandex.net', port=443): Max retries exceeded with url: /v1/disk/resources?path=disk%3A%2F%D0%90%D1%80%D1%85%D0%B8%D0%B2%D1%8B&limit=500&fields=type%2C_embedded%2C_embedded.offset%2C_embedded.limit%2C_embedded.total%2C_embedded.items (Caused by ConnectTimeoutError(<urllib3.connection.HTTPSConnection object at 0x00000192A764B4D0>, 'Connection to cloud-api.yandex.net timed out. (connect timeout=10.0)'))
Got the error after 3 retry attempts
2025-07-08 11:33:34,916 - __main__ - ERROR - save_files:56 - Критическая ошибка в make_and_write_archive HTTPSConnectionPool(host='cloud-api.yandex.net', port=443): Max retries exceeded with url: /v1/disk/resources?path=disk%3A%2F%D0%90%D1%80%D1%85%D0%B8%D0%B2%D1%8B&limit=500&fields=type%2C_embedded%2C_embedded.offset%2C_embedded.limit%2C_embedded.total%2C_embedded.items (Caused by ConnectTimeoutError(<urllib3.connection.HTTPSConnection object at 0x00000192A764B4D0>, 'Connection to cloud-api.yandex.net timed out. (connect timeout=10.0)'))
Traceback (most recent call last):
  File "C:\PycharmProjects\Save\.venv\Lib\site-packages\urllib3\connection.py", line 198, in _new_conn
    sock = connection.create_connection(
        (self._dns_host, self.port),
    ...<2 lines>...
        socket_options=self.socket_options,
    )
  File "C:\PycharmProjects\Save\.venv\Lib\site-packages\urllib3\util\connection.py", line 85, in create_connection
    raise err
  File "C:\PycharmProjects\Save\.venv\Lib\site-packages\urllib3\util\connection.py", line 73, in create_connection
    sock.connect(sa)
    ~~~~~~~~~~~~^^^^
TimeoutError: timed out

The above exception was the direct cause of the following exception:

Traceback (most recent call last):
  File "C:\PycharmProjects\Save\.venv\Lib\site-packages\urllib3\connectionpool.py", line 787, in urlopen
    response = self._make_request(
        conn,
    ...<10 lines>...
        **response_kw,
    )
  File "C:\PycharmProjects\Save\.venv\Lib\site-packages\urllib3\connectionpool.py", line 488, in _make_request
    raise new_e
  File "C:\PycharmProjects\Save\.venv\Lib\site-packages\urllib3\connectionpool.py", line 464, in _make_request
    self._validate_conn(conn)
    ~~~~~~~~~~~~~~~~~~~^^^^^^
  File "C:\PycharmProjects\Save\.venv\Lib\site-packages\urllib3\connectionpool.py", line 1093, in _validate_conn
    conn.connect()
    ~~~~~~~~~~~~^^
  File "C:\PycharmProjects\Save\.venv\Lib\site-packages\urllib3\connection.py", line 704, in connect
    self.sock = sock = self._new_conn()
                       ~~~~~~~~~~~~~~^^
  File "C:\PycharmProjects\Save\.venv\Lib\site-packages\urllib3\connection.py", line 207, in _new_conn
    raise ConnectTimeoutError(
    ...<2 lines>...
    ) from e
urllib3.exceptions.ConnectTimeoutError: (<urllib3.connection.HTTPSConnection object at 0x00000192A764B4D0>, 'Connection to cloud-api.yandex.net timed out. (connect timeout=10.0)')

The above exception was the direct cause of the following exception:

Traceback (most recent call last):
  File "C:\PycharmProjects\Save\.venv\Lib\site-packages\requests\adapters.py", line 667, in send
    resp = conn.urlopen(
        method=request.method,
    ...<9 lines>...
        chunked=chunked,
    )
  File "C:\PycharmProjects\Save\.venv\Lib\site-packages\urllib3\connectionpool.py", line 841, in urlopen
    retries = retries.increment(
        method, url, error=new_e, _pool=self, _stacktrace=sys.exc_info()[2]
    )
  File "C:\PycharmProjects\Save\.venv\Lib\site-packages\urllib3\util\retry.py", line 519, in increment
    raise MaxRetryError(_pool, url, reason) from reason  # type: ignore[arg-type]
    ^^^^^^^^^^^^^^^^^^^^^^^^^^^^^^^^^^^^^^^^^^^^^^^^^^^
urllib3.exceptions.MaxRetryError: HTTPSConnectionPool(host='cloud-api.yandex.net', port=443): Max retries exceeded with url: /v1/disk/resources?path=disk%3A%2F%D0%90%D1%80%D1%85%D0%B8%D0%B2%D1%8B&limit=500&fields=type%2C_embedded%2C_embedded.offset%2C_embedded.limit%2C_embedded.total%2C_embedded.items (Caused by ConnectTimeoutError(<urllib3.connection.HTTPSConnection object at 0x00000192A764B4D0>, 'Connection to cloud-api.yandex.net timed out. (connect timeout=10.0)'))

During handling of the above exception, another exception occurred:

Traceback (most recent call last):
  File "C:\PycharmProjects\Save\.venv\Lib\site-packages\yadisk\sessions\requests_session.py", line 163, in send_request
    self.requests_session.request(method, url, **converted_kwargs)
    ~~~~~~~~~~~~~~~~~~~~~~~~~~~~~^^^^^^^^^^^^^^^^^^^^^^^^^^^^^^^^^
  File "C:\PycharmProjects\Save\.venv\Lib\site-packages\requests\sessions.py", line 589, in request
    resp = self.send(prep, **send_kwargs)
  File "C:\PycharmProjects\Save\.venv\Lib\site-packages\requests\sessions.py", line 703, in send
    r = adapter.send(request, **kwargs)
  File "C:\PycharmProjects\Save\.venv\Lib\site-packages\requests\adapters.py", line 688, in send
    raise ConnectTimeout(e, request=request)
requests.exceptions.ConnectTimeout: HTTPSConnectionPool(host='cloud-api.yandex.net', port=443): Max retries exceeded with url: /v1/disk/resources?path=disk%3A%2F%D0%90%D1%80%D1%85%D0%B8%D0%B2%D1%8B&limit=500&fields=type%2C_embedded%2C_embedded.offset%2C_embedded.limit%2C_embedded.total%2C_embedded.items (Caused by ConnectTimeoutError(<urllib3.connection.HTTPSConnection object at 0x00000192A764B4D0>, 'Connection to cloud-api.yandex.net timed out. (connect timeout=10.0)'))

The above exception was the direct cause of the following exception:

Traceback (most recent call last):
  File "C:\PycharmProjects\Save\SRC\save_files.py", line 54, in make_and_write_archive
    self.upload_to_yandex_disk(archive_path)
    ~~~~~~~~~~~~~~~~~~~~~~~~~~^^^^^^^^^^^^^^
  File "C:\PycharmProjects\Save\SRC\save_files.py", line 81, in upload_to_yandex_disk
    if not yandex_disk.write_archive_fast(archive_path):
           ~~~~~~~~~~~~~~~~~~~~~~~~~~~~~~^^^^^^^^^^^^^^
  File "C:\PycharmProjects\Save\SRC\yandex_disk.py", line 236, in write_archive_fast
    upload_url, remote_path = self.get_file_download_URL()
                              ~~~~~~~~~~~~~~~~~~~~~~~~~~^^
  File "C:\PycharmProjects\Save\SRC\yandex_disk.py", line 313, in get_file_download_URL
    archive_name = self.create_archive_name()
  File "C:\PycharmProjects\Save\SRC\yandex_disk.py", line 86, in create_archive_name
    file_nums = self._get_file_nums()
  File "C:\PycharmProjects\Save\SRC\yandex_disk.py", line 109, in _get_file_nums
    for item in self.disk.listdir(self.archive_path):
                ~~~~~~~~~~~~~~~~~^^^^^^^^^^^^^^^^^^^
  File "C:\PycharmProjects\Save\.venv\Lib\site-packages\yadisk\_client.py", line 133, in _listdir
    result = get_meta_function(path, _then=_validate_listdir_response, **kwargs)
  File "C:\PycharmProjects\Save\.venv\Lib\site-packages\yadisk\_client.py", line 773, in get_meta
    return GetMetaRequest(self.session, path, **kwargs).send(yadisk=self, then=_then)
           ~~~~~~~~~~~~~~~~~~~~~~~~~~~~~~~~~~~~~~~~~~~~~~~~~^^^^^^^^^^^^^^^^^^^^^^^^^
  File "C:\PycharmProjects\Save\.venv\Lib\site-packages\yadisk\_api\api_request.py", line 241, in send
    return auto_retry(
        self._attempt,
    ...<3 lines>...
        retry_on=self.retry_on
    )
  File "C:\PycharmProjects\Save\.venv\Lib\site-packages\yadisk\utils.py", line 198, in auto_retry
    return func(*args, **kwargs)
  File "C:\PycharmProjects\Save\.venv\Lib\site-packages\yadisk\_api\api_request.py", line 157, in _attempt
    response = session.send_request(self.method, self.url, **kwargs)
  File "C:\PycharmProjects\Save\.venv\Lib\site-packages\yadisk\sessions\requests_session.py", line 166, in send_request
    raise convert_requests_exception(e) from e
yadisk.exceptions.RequestTimeoutError: HTTPSConnectionPool(host='cloud-api.yandex.net', port=443): Max retries exceeded with url: /v1/disk/resources?path=disk%3A%2F%D0%90%D1%80%D1%85%D0%B8%D0%B2%D1%8B&limit=500&fields=type%2C_embedded%2C_embedded.offset%2C_embedded.limit%2C_embedded.total%2C_embedded.items (Caused by ConnectTimeoutError(<urllib3.connection.HTTPSConnection object at 0x00000192A764B4D0>, 'Connection to cloud-api.yandex.net timed out. (connect timeout=10.0)'))
Got the error after 3 retry attempts
2025-07-08 11:33:34,921 - main - ERROR - save_files:164 - Критическая ошибка при формировании или записи архива в облако
Traceback (most recent call last):
  File "C:\PycharmProjects\Save\.venv\Lib\site-packages\urllib3\connection.py", line 198, in _new_conn
    sock = connection.create_connection(
        (self._dns_host, self.port),
    ...<2 lines>...
        socket_options=self.socket_options,
    )
  File "C:\PycharmProjects\Save\.venv\Lib\site-packages\urllib3\util\connection.py", line 85, in create_connection
    raise err
  File "C:\PycharmProjects\Save\.venv\Lib\site-packages\urllib3\util\connection.py", line 73, in create_connection
    sock.connect(sa)
    ~~~~~~~~~~~~^^^^
TimeoutError: timed out

The above exception was the direct cause of the following exception:

Traceback (most recent call last):
  File "C:\PycharmProjects\Save\.venv\Lib\site-packages\urllib3\connectionpool.py", line 787, in urlopen
    response = self._make_request(
        conn,
    ...<10 lines>...
        **response_kw,
    )
  File "C:\PycharmProjects\Save\.venv\Lib\site-packages\urllib3\connectionpool.py", line 488, in _make_request
    raise new_e
  File "C:\PycharmProjects\Save\.venv\Lib\site-packages\urllib3\connectionpool.py", line 464, in _make_request
    self._validate_conn(conn)
    ~~~~~~~~~~~~~~~~~~~^^^^^^
  File "C:\PycharmProjects\Save\.venv\Lib\site-packages\urllib3\connectionpool.py", line 1093, in _validate_conn
    conn.connect()
    ~~~~~~~~~~~~^^
  File "C:\PycharmProjects\Save\.venv\Lib\site-packages\urllib3\connection.py", line 704, in connect
    self.sock = sock = self._new_conn()
                       ~~~~~~~~~~~~~~^^
  File "C:\PycharmProjects\Save\.venv\Lib\site-packages\urllib3\connection.py", line 207, in _new_conn
    raise ConnectTimeoutError(
    ...<2 lines>...
    ) from e
urllib3.exceptions.ConnectTimeoutError: (<urllib3.connection.HTTPSConnection object at 0x00000192A764B4D0>, 'Connection to cloud-api.yandex.net timed out. (connect timeout=10.0)')

The above exception was the direct cause of the following exception:

Traceback (most recent call last):
  File "C:\PycharmProjects\Save\.venv\Lib\site-packages\requests\adapters.py", line 667, in send
    resp = conn.urlopen(
        method=request.method,
    ...<9 lines>...
        chunked=chunked,
    )
  File "C:\PycharmProjects\Save\.venv\Lib\site-packages\urllib3\connectionpool.py", line 841, in urlopen
    retries = retries.increment(
        method, url, error=new_e, _pool=self, _stacktrace=sys.exc_info()[2]
    )
  File "C:\PycharmProjects\Save\.venv\Lib\site-packages\urllib3\util\retry.py", line 519, in increment
    raise MaxRetryError(_pool, url, reason) from reason  # type: ignore[arg-type]
    ^^^^^^^^^^^^^^^^^^^^^^^^^^^^^^^^^^^^^^^^^^^^^^^^^^^
urllib3.exceptions.MaxRetryError: HTTPSConnectionPool(host='cloud-api.yandex.net', port=443): Max retries exceeded with url: /v1/disk/resources?path=disk%3A%2F%D0%90%D1%80%D1%85%D0%B8%D0%B2%D1%8B&limit=500&fields=type%2C_embedded%2C_embedded.offset%2C_embedded.limit%2C_embedded.total%2C_embedded.items (Caused by ConnectTimeoutError(<urllib3.connection.HTTPSConnection object at 0x00000192A764B4D0>, 'Connection to cloud-api.yandex.net timed out. (connect timeout=10.0)'))

During handling of the above exception, another exception occurred:

Traceback (most recent call last):
  File "C:\PycharmProjects\Save\.venv\Lib\site-packages\yadisk\sessions\requests_session.py", line 163, in send_request
    self.requests_session.request(method, url, **converted_kwargs)
    ~~~~~~~~~~~~~~~~~~~~~~~~~~~~~^^^^^^^^^^^^^^^^^^^^^^^^^^^^^^^^^
  File "C:\PycharmProjects\Save\.venv\Lib\site-packages\requests\sessions.py", line 589, in request
    resp = self.send(prep, **send_kwargs)
  File "C:\PycharmProjects\Save\.venv\Lib\site-packages\requests\sessions.py", line 703, in send
    r = adapter.send(request, **kwargs)
  File "C:\PycharmProjects\Save\.venv\Lib\site-packages\requests\adapters.py", line 688, in send
    raise ConnectTimeout(e, request=request)
requests.exceptions.ConnectTimeout: HTTPSConnectionPool(host='cloud-api.yandex.net', port=443): Max retries exceeded with url: /v1/disk/resources?path=disk%3A%2F%D0%90%D1%80%D1%85%D0%B8%D0%B2%D1%8B&limit=500&fields=type%2C_embedded%2C_embedded.offset%2C_embedded.limit%2C_embedded.total%2C_embedded.items (Caused by ConnectTimeoutError(<urllib3.connection.HTTPSConnection object at 0x00000192A764B4D0>, 'Connection to cloud-api.yandex.net timed out. (connect timeout=10.0)'))

The above exception was the direct cause of the following exception:

Traceback (most recent call last):
  File "C:\PycharmProjects\Save\SRC\save_files.py", line 160, in <module>
    save_files.make_and_write_archive()
    ~~~~~~~~~~~~~~~~~~~~~~~~~~~~~~~~~^^
  File "C:\PycharmProjects\Save\SRC\save_files.py", line 54, in make_and_write_archive
    self.upload_to_yandex_disk(archive_path)
    ~~~~~~~~~~~~~~~~~~~~~~~~~~^^^^^^^^^^^^^^
  File "C:\PycharmProjects\Save\SRC\save_files.py", line 81, in upload_to_yandex_disk
    if not yandex_disk.write_archive_fast(archive_path):
           ~~~~~~~~~~~~~~~~~~~~~~~~~~~~~~^^^^^^^^^^^^^^
  File "C:\PycharmProjects\Save\SRC\yandex_disk.py", line 236, in write_archive_fast
    upload_url, remote_path = self.get_file_download_URL()
                              ~~~~~~~~~~~~~~~~~~~~~~~~~~^^
  File "C:\PycharmProjects\Save\SRC\yandex_disk.py", line 313, in get_file_download_URL
    archive_name = self.create_archive_name()
  File "C:\PycharmProjects\Save\SRC\yandex_disk.py", line 86, in create_archive_name
    file_nums = self._get_file_nums()
  File "C:\PycharmProjects\Save\SRC\yandex_disk.py", line 109, in _get_file_nums
    for item in self.disk.listdir(self.archive_path):
                ~~~~~~~~~~~~~~~~~^^^^^^^^^^^^^^^^^^^
  File "C:\PycharmProjects\Save\.venv\Lib\site-packages\yadisk\_client.py", line 133, in _listdir
    result = get_meta_function(path, _then=_validate_listdir_response, **kwargs)
  File "C:\PycharmProjects\Save\.venv\Lib\site-packages\yadisk\_client.py", line 773, in get_meta
    return GetMetaRequest(self.session, path, **kwargs).send(yadisk=self, then=_then)
           ~~~~~~~~~~~~~~~~~~~~~~~~~~~~~~~~~~~~~~~~~~~~~~~~~^^^^^^^^^^^^^^^^^^^^^^^^^
  File "C:\PycharmProjects\Save\.venv\Lib\site-packages\yadisk\_api\api_request.py", line 241, in send
    return auto_retry(
        self._attempt,
    ...<3 lines>...
        retry_on=self.retry_on
    )
  File "C:\PycharmProjects\Save\.venv\Lib\site-packages\yadisk\utils.py", line 198, in auto_retry
    return func(*args, **kwargs)
  File "C:\PycharmProjects\Save\.venv\Lib\site-packages\yadisk\_api\api_request.py", line 157, in _attempt
    response = session.send_request(self.method, self.url, **kwargs)
  File "C:\PycharmProjects\Save\.venv\Lib\site-packages\yadisk\sessions\requests_session.py", line 166, in send_request
    raise convert_requests_exception(e) from e
yadisk.exceptions.RequestTimeoutError: HTTPSConnectionPool(host='cloud-api.yandex.net', port=443): Max retries exceeded with url: /v1/disk/resources?path=disk%3A%2F%D0%90%D1%80%D1%85%D0%B8%D0%B2%D1%8B&limit=500&fields=type%2C_embedded%2C_embedded.offset%2C_embedded.limit%2C_embedded.total%2C_embedded.items (Caused by ConnectTimeoutError(<urllib3.connection.HTTPSConnection object at 0x00000192A764B4D0>, 'Connection to cloud-api.yandex.net timed out. (connect timeout=10.0)'))
Got the error after 3 retry attempts
2025-07-08 12:15:35,268 - main - INFO - save_files:156 - Запуск приложения резервного копирования
2025-07-08 12:15:35,268 - __main__ - INFO - save_files:22 - Инициализация SaveFiles
2025-07-08 12:15:35,292 - __main__ - INFO - save_files:50 - Начало создания и загрузки архива
2025-07-08 12:15:35,292 - arch_7z_spec - INFO - arch_7z_spec:115 - Запуск архивации: ['C:\\Users\\LB\\Downloads\\7-Zip\\7z.exe', 'a', '-p***************', '-mhe=on', '-sfx', 'C:\\Users\\LB\\AppData\\Local\\Temp\\tmpvg6d5hcy\\archive.exe', '@C:\\PycharmProjects\\Save\\list.txt', '-bso0', '-bsp0']
2025-07-08 12:15:39,975 - arch_7z_spec - INFO - arch_7z_spec:140 - Архивация завершена успешно
2025-07-08 12:15:39,975 - __main__ - INFO - save_files:74 - Архив успешно создан
2025-07-08 12:15:39,975 - yandex_disk - INFO - yandex_disk:51 - Инициализация YandexDisk
2025-07-08 12:15:39,975 - yandex_disk - INFO - yandex_disk:67 - Получение токена авторизации
2025-07-08 12:15:39,977 - __main__ - INFO - save_files:79 - Начало загрузки на Яндекс.Диск
2025-07-08 12:15:39,977 - yandex_disk - INFO - yandex_disk:231 - Быстрая загрузка файла C:\Users\LB\AppData\Local\Temp\tmpvg6d5hcy\archive.exe
2025-07-08 12:15:39,977 - yandex_disk - INFO - yandex_disk:81 - Генерация имени архива
2025-07-08 12:15:40,527 - yandex_disk - INFO - yandex_disk:93 - Сгенерировано имя архива: archive_2025_07_08_2.exe
2025-07-08 12:15:41,225 - yandex_disk - INFO - yandex_disk:237 - Начало быстрой загрузки файла C:\Users\LB\AppData\Local\Temp\tmpvg6d5hcy\archive.exe
2025-07-08 12:15:45,934 - yandex_disk - INFO - yandex_disk:242 - Файл C:\Users\LB\AppData\Local\Temp\tmpvg6d5hcy\archive.exe успешно загружен в archive_2025_07_08_2.exe
2025-07-08 12:15:45,934 - __main__ - INFO - save_files:85 - Архив успешно загружен на Яндекс.Диск
2025-07-08 12:15:45,942 - main - INFO - save_files:161 - Процесс завершен успешно
2025-07-08 15:07:56,629 - main - INFO - save_files:156 - Запуск приложения резервного копирования
2025-07-08 15:07:56,629 - __main__ - INFO - save_files:22 - Инициализация SaveFiles
2025-07-08 15:07:56,654 - __main__ - INFO - save_files:50 - Начало создания и загрузки архива
2025-07-08 15:07:56,654 - arch_7z_spec - INFO - arch_7z_spec:115 - Запуск архивации: ['C:\\Users\\LB\\Downloads\\7-Zip\\7z.exe', 'a', '-p***************', '-mhe=on', '-sfx', 'C:\\Users\\LB\\AppData\\Local\\Temp\\tmpwk5q4z8v\\archive.exe', '@C:\\PycharmProjects\\Save\\list.txt', '-bso0', '-bsp0']
2025-07-08 15:08:01,454 - arch_7z_spec - INFO - arch_7z_spec:140 - Архивация завершена успешно
2025-07-08 15:08:01,454 - __main__ - INFO - save_files:74 - Архив успешно создан
2025-07-08 15:08:01,454 - yandex_disk - INFO - yandex_disk:51 - Инициализация YandexDisk
2025-07-08 15:08:01,454 - yandex_disk - INFO - yandex_disk:67 - Получение токена авторизации
2025-07-08 15:08:01,455 - __main__ - INFO - save_files:79 - Начало загрузки на Яндекс.Диск
2025-07-08 15:08:01,455 - yandex_disk - INFO - yandex_disk:239 - Быстрая загрузка файла C:\Users\LB\AppData\Local\Temp\tmpwk5q4z8v\archive.exe
2025-07-08 15:08:01,455 - yandex_disk - INFO - yandex_disk:86 - Генерация имени архива
2025-07-08 15:08:02,309 - yandex_disk - INFO - yandex_disk:98 - Сгенерировано имя архива: archive_2025_07_08_3.exe
2025-07-08 15:08:03,293 - yandex_disk - INFO - yandex_disk:245 - Начало быстрой загрузки файла C:\Users\LB\AppData\Local\Temp\tmpwk5q4z8v\archive.exe
2025-07-08 15:08:48,452 - yandex_disk - INFO - yandex_disk:250 - Файл C:\Users\LB\AppData\Local\Temp\tmpwk5q4z8v\archive.exe успешно загружен в archive_2025_07_08_3.exe
2025-07-08 15:08:48,453 - __main__ - INFO - save_files:85 - Архив успешно загружен на Яндекс.Диск
2025-07-08 15:08:48,462 - main - INFO - save_files:161 - Процесс завершен успешно
